Workbook
Name cwd: Parameters!$B$2
Name Data_Patch_Color_Lookup: 'Data Patch'!$F$1:$F$231
Name Data_Patch_Lookup: 'Data Patch'!$B$1:$B$231
Name filename: Parameters!$B$3

Sheet DATA
A1: TYPE | B1: UNIVERSE
B2: 1 | F2: Gig Name: | G2: Untitled Show
A3: SNEAK | B3: 2
A4: SINGLE | B4: 3
A5: OPTI PATCH | B5: 4
B6: 5
B7: 6
B8: 7
B9: 8
B10: 9
B11: 10
B12: 11
B13: 12
B14: 13
B15: 14
B16: 15
B17: 16
... B257: 256

Sheet NODE40
A1: NODE 40 | J1: =DATA!$G$2 -> Untitled Show | Q1: #VALUE!
A2: NODE1 | B2: PORT1 | C2: PORT2 | D2: PORT3 | E2: PORT4 | F2: PORT5 | G2: PORT6 | H2: PORT7 | I2: PORT8 | M2: Outlet Count | N2: =COUNTA(Data_Patch[Outlet ID]) -> 144
A3: sACN | B3: =_xlfn.XLOOKUP($A$2&"-"&B$2, Data_Patch[Outlet ID], Data_Patch[Universe], "") -> 1 | C3: =_xlfn.XLOOKUP($A$2&"-"&C$2, Data_Patch[Outlet ID], Data_Patch[Universe], "") -> 2 | D3: =_xlfn.XLOOKUP($A$2&"-"&D$2, Data_Patch[Outlet ID], Data_Patch[Universe], "") -> 0 | E3: =_xlfn.XLOOKUP($A$2&"-"&E$2, Data_Patch[Outlet ID], Data_Patch[Universe], "") -> 0 | F3: =_xlfn.XLOOKUP($A$2&"-"&F$2, Data_Patch[Outlet ID], Data_Patch[Universe], "") -> 12 | G3: =_xlfn.XLOOKUP($A$2&"-"&G$2, Data_Patch[Outlet ID], Data_Patch[Universe], "") -> 13 | H3: =_xlfn.XLOOKUP($A$2&"-"&H$2, Data_Patch[Outlet ID], Data_Patch[Universe], "") -> 0 | I3: =_xlfn.XLOOKUP($A$2&"-"&I$2, Data_Patch[Outlet ID], Data_Patch[Universe], "") -> 0 | J3: UNIVERSE | M3: Outlets | N3: 40
A4: IP 192.168.0.xxx | B4: =_xlfn.XLOOKUP($A$2&"-"&B$2, Data_Patch[Outlet ID], Data_Patch[Cable], "") -> DSB1 | C4: =_xlfn.XLOOKUP($A$2&"-"&C$2, Data_Patch[Outlet ID], Data_Patch[Cable], "") -> DSB2 | D4: =_xlfn.XLOOKUP($A$2&"-"&D$2, Data_Patch[Outlet ID], Data_Patch[Cable], "") | E4: =_xlfn.XLOOKUP($A$2&"-"&E$2, Data_Patch[Outlet ID], Data_Patch[Cable], "") | F4: =_xlfn.XLOOKUP($A$2&"-"&F$2, Data_Patch[Outlet ID], Data_Patch[Cable], "") -> SLW1 | G4: =_xlfn.XLOOKUP($A$2&"-"&G$2, Data_Patch[Outlet ID], Data_Patch[Cable], "") -> SLW2 | H4: =_xlfn.XLOOKUP($A$2&"-"&H$2, Data_Patch[Outlet ID], Data_Patch[Cable], "") | I4: =_xlfn.XLOOKUP($A$2&"-"&I$2, Data_Patch[Outlet ID], Data_Patch[Cable], "") | J4: CABLE
B5: =_xlfn.XLOOKUP($A$2&"-"&B$2, Data_Patch[Outlet ID], Data_Patch[Type], "") -> Sneak | C5: =_xlfn.XLOOKUP($A$2&"-"&C$2, Data_Patch[Outlet ID], Data_Patch[Type], "") -> Sneak | D5: =_xlfn.XLOOKUP($A$2&"-"&D$2, Data_Patch[Outlet ID], Data_Patch[Type], "") | E5: =_xlfn.XLOOKUP($A$2&"-"&E$2, Data_Patch[Outlet ID], Data_Patch[Type], "") | F5: =_xlfn.XLOOKUP($A$2&"-"&F$2, Data_Patch[Outlet ID], Data_Patch[Type], "") -> Sneak | G5: =_xlfn.XLOOKUP($A$2&"-"&G$2, Data_Patch[Outlet ID], Data_Patch[Type], "") -> Sneak | H5: =_xlfn.XLOOKUP($A$2&"-"&H$2, Data_Patch[Outlet ID], Data_Patch[Type], "") | I5: =_xlfn.XLOOKUP($A$2&"-"&I$2, Data_Patch[Outlet ID], Data_Patch[Type], "") | J5: TYPE
A7: NODE2 | B7: PORT1 | C7: PORT2 | D7: PORT3 | E7: PORT4 | F7: PORT5 | G7: PORT6 | H7: PORT7 | I7: PORT8
A8: sACN | B8: =_xlfn.XLOOKUP($A$7&"-"&B$7, Data_Patch[Outlet ID], Data_Patch[Universe], "") -> 0 | C8: =_xlfn.XLOOKUP($A$7&"-"&C$7, Data_Patch[Outlet ID], Data_Patch[Universe], "") -> 0 | D8: =_xlfn.XLOOKUP($A$7&"-"&D$7, Data_Patch[Outlet ID], Data_Patch[Universe], "") -> 0 | E8: =_xlfn.XLOOKUP($A$7&"-"&E$7, Data_Patch[Outlet ID], Data_Patch[Universe], "") -> 0 | F8: =_xlfn.XLOOKUP($A$7&"-"&F$7, Data_Patch[Outlet ID], Data_Patch[Universe], "") -> 0 | G8: =_xlfn.XLOOKUP($A$7&"-"&G$7, Data_Patch[Outlet ID], Data_Patch[Universe], "") -> 0 | H8: =_xlfn.XLOOKUP($A$7&"-"&H$7, Data_Patch[Outlet ID], Data_Patch[Universe], "") -> 0 | I8: =_xlfn.XLOOKUP($A$7&"-"&I$7, Data_Patch[Outlet ID], Data_Patch[Universe], "") -> 0 | J8: UNIVERSE
A9: IP 192.168.0.xxx | B9: =_xlfn.XLOOKUP($A$7&"-"&B$7, Data_Patch[Outlet ID], Data_Patch[Cable], "") | C9: =_xlfn.XLOOKUP($A$7&"-"&C$7, Data_Patch[Outlet ID], Data_Patch[Cable], "") | D9: =_xlfn.XLOOKUP($A$7&"-"&D$7, Data_Patch[Outlet ID], Data_Patch[Cable], "") | E9: =_xlfn.XLOOKUP($A$7&"-"&E$7, Data_Patch[Outlet ID], Data_Patch[Cable], "") | F9: =_xlfn.XLOOKUP($A$7&"-"&F$7, Data_Patch[Outlet ID], Data_Patch[Cable], "") | G9: =_xlfn.XLOOKUP($A$7&"-"&G$7, Data_Patch[Outlet ID], Data_Patch[Cable], "") | H9: =_xlfn.XLOOKUP($A$7&"-"&H$7, Data_Patch[Outlet ID], Data_Patch[Cable], "") | I9: =_xlfn.XLOOKUP($A$7&"-"&I$7, Data_Patch[Outlet ID], Data_Patch[Cable], "") | J9: CABLE
B10: =_xlfn.XLOOKUP($A$7&"-"&B$7, Data_Patch[Outlet ID], Data_Patch[Type], "") | C10: =_xlfn.XLOOKUP($A$7&"-"&C$7, Data_Patch[Outlet ID], Data_Patch[Type], "") | D10: =_xlfn.XLOOKUP($A$7&"-"&D$7, Data_Patch[Outlet ID], Data_Patch[Type], "") | E10: =_xlfn.XLOOKUP($A$7&"-"&E$7, Data_Patch[Outlet ID], Data_Patch[Type], "") | F10: =_xlfn.XLOOKUP($A$7&"-"&F$7, Data_Patch[Outlet ID], Data_Patch[Type], "") | G10: =_xlfn.XLOOKUP($A$7&"-"&G$7, Data_Patch[Outlet ID], Data_Patch[Type], "") | H10: =_xlfn.XLOOKUP($A$7&"-"&H$7, Data_Patch[Outlet ID], Data_Patch[Type], "") | I10: =_xlfn.XLOOKUP($A$7&"-"&I$7, Data_Patch[Outlet ID], Data_Patch[Type], "") | J10: TYPE | Q10: =_xlfn.XLOOKUP($A$2&"-"&B$2, Data_Patch[Outlet ID], Data_Patch[Cable], "") -> DSB1
A12: NODE3 | B12: PORT1 | C12: PORT2 | D12: PORT3 | E12: PORT4 | F12: PORT5 | G12: PORT6 | H12: PORT7 | I12: PORT8
A13: sACN | B13: =_xlfn.XLOOKUP($A$12&"-"&B$12, Data_Patch[Outlet ID], Data_Patch[Universe], "") -> 0 | C13: =_xlfn.XLOOKUP($A$12&"-"&C$12, Data_Patch[Outlet ID], Data_Patch[Universe], "") -> 0 | D13: =_xlfn.XLOOKUP($A$12&"-"&D$12, Data_Patch[Outlet ID], Data_Patch[Universe], "") -> 0 | E13: =_xlfn.XLOOKUP($A$12&"-"&E$12, Data_Patch[Outlet ID], Data_Patch[Universe], "") -> 0 | F13: =_xlfn.XLOOKUP($A$12&"-"&F$12, Data_Patch[Outlet ID], Data_Patch[Universe], "") -> 0 | G13: =_xlfn.XLOOKUP($A$12&"-"&G$12, Data_Patch[Outlet ID], Data_Patch[Universe], "") -> 0 | H13: =_xlfn.XLOOKUP($A$12&"-"&H$12, Data_Patch[Outlet ID], Data_Patch[Universe], "") -> 0 | I13: =_xlfn.XLOOKUP($A$12&"-"&I$12, Data_Patch[Outlet ID], Data_Patch[Universe], "") -> 0 | J13: UNIVERSE
A14: IP 192.168.0.xxx | B14: =_xlfn.XLOOKUP($A$12&"-"&B$12, Data_Patch[Outlet ID], Data_Patch[Cable], "") | C14: =_xlfn.XLOOKUP($A$12&"-"&C$12, Data_Patch[Outlet ID], Data_Patch[Cable], "") | D14: =_xlfn.XLOOKUP($A$12&"-"&D$12, Data_Patch[Outlet ID], Data_Patch[Cable], "") | E14: =_xlfn.XLOOKUP($A$12&"-"&E$12, Data_Patch[Outlet ID], Data_Patch[Cable], "") | F14: =_xlfn.XLOOKUP($A$12&"-"&F$12, Data_Patch[Outlet ID], Data_Patch[Cable], "") | G14: =_xlfn.XLOOKUP($A$12&"-"&G$12, Data_Patch[Outlet ID], Data_Patch[Cable], "") | H14: =_xlfn.XLOOKUP($A$12&"-"&H$12, Data_Patch[Outlet ID], Data_Patch[Cable], "") | I14: =_xlfn.XLOOKUP($A$12&"-"&I$12, Data_Patch[Outlet ID], Data_Patch[Cable], "") | J14: CABLE
B15: =_xlfn.XLOOKUP($A$12&"-"&B$12, Data_Patch[Outlet ID], Data_Patch[Type], "") | C15: =_xlfn.XLOOKUP($A$12&"-"&C$12, Data_Patch[Outlet ID], Data_Patch[Type], "") | D15: =_xlfn.XLOOKUP($A$12&"-"&D$12, Data_Patch[Outlet ID], Data_Patch[Type], "") | E15: =_xlfn.XLOOKUP($A$12&"-"&E$12, Data_Patch[Outlet ID], Data_Patch[Type], "") | F15: =_xlfn.XLOOKUP($A$12&"-"&F$12, Data_Patch[Outlet ID], Data_Patch[Type], "") | G15: =_xlfn.XLOOKUP($A$12&"-"&G$12, Data_Patch[Outlet ID], Data_Patch[Type], "") | H15: =_xlfn.XLOOKUP($A$12&"-"&H$12, Data_Patch[Outlet ID], Data_Patch[Type], "") | I15: =_xlfn.XLOOKUP($A$12&"-"&I$12, Data_Patch[Outlet ID], Data_Patch[Type], "") | J15: TYPE
A17: NODE4 | B17: PORT1 | C17: PORT2 | D17: PORT3 | E17: PORT4 | F17: PORT5 | G17: PORT6 | H17: PORT7 | I17: PORT8
A18: sACN | B18: =_xlfn.XLOOKUP($A$17&"-"&B$17, Data_Patch[Outlet ID], Data_Patch[Universe], "") -> 0 | C18: =_xlfn.XLOOKUP($A$17&"-"&C$17, Data_Patch[Outlet ID], Data_Patch[Universe], "") -> 0 | D18: =_xlfn.XLOOKUP($A$17&"-"&D$17, Data_Patch[Outlet ID], Data_Patch[Universe], "") -> 0 | E18: =_xlfn.XLOOKUP($A$17&"-"&E$17, Data_Patch[Outlet ID], Data_Patch[Universe], "") -> 0 | F18: =_xlfn.XLOOKUP($A$17&"-"&F$17, Data_Patch[Outlet ID], Data_Patch[Universe], "") -> 0 | G18: =_xlfn.XLOOKUP($A$17&"-"&G$17, Data_Patch[Outlet ID], Data_Patch[Universe], "") -> 0 | H18: =_xlfn.XLOOKUP($A$17&"-"&H$17, Data_Patch[Outlet ID], Data_Patch[Universe], "") -> 0 | I18: =_xlfn.XLOOKUP($A$17&"-"&I$17, Data_Patch[Outlet ID], Data_Patch[Universe], "") -> 0 | J18: UNIVERSE
A19: IP 192.168.0.xxx | B19: =_xlfn.XLOOKUP($A$17&"-"&B$17, Data_Patch[Outlet ID], Data_Patch[Cable], "") | C19: =_xlfn.XLOOKUP($A$17&"-"&C$17, Data_Patch[Outlet ID], Data_Patch[Cable], "") | D19: =_xlfn.XLOOKUP($A$17&"-"&D$17, Data_Patch[Outlet ID], Data_Patch[Cable], "") | E19: =_xlfn.XLOOKUP($A$17&"-"&E$17, Data_Patch[Outlet ID], Data_Patch[Cable], "") | F19: =_xlfn.XLOOKUP($A$17&"-"&F$17, Data_Patch[Outlet ID], Data_Patch[Cable], "") | G19: =_xlfn.XLOOKUP($A$17&"-"&G$17, Data_Patch[Outlet ID], Data_Patch[Cable], "") | H19: =_xlfn.XLOOKUP($A$17&"-"&H$17, Data_Patch[Outlet ID], Data_Patch[Cable], "") | I19: =_xlfn.XLOOKUP($A$17&"-"&I$17, Data_Patch[Outlet ID], Data_Patch[Cable], "") | J19: CABLE
B20: =_xlfn.XLOOKUP($A$17&"-"&B$17, Data_Patch[Outlet ID], Data_Patch[Type], "") | C20: =_xlfn.XLOOKUP($A$17&"-"&C$17, Data_Patch[Outlet ID], Data_Patch[Type], "") | D20: =_xlfn.XLOOKUP($A$17&"-"&D$17, Data_Patch[Outlet ID], Data_Patch[Type], "") | E20: =_xlfn.XLOOKUP($A$17&"-"&E$17, Data_Patch[Outlet ID], Data_Patch[Type], "") | F20: =_xlfn.XLOOKUP($A$17&"-"&F$17, Data_Patch[Outlet ID], Data_Patch[Type], "") | G20: =_xlfn.XLOOKUP($A$17&"-"&G$17, Data_Patch[Outlet ID], Data_Patch[Type], "") | H20: =_xlfn.XLOOKUP($A$17&"-"&H$17, Data_Patch[Outlet ID], Data_Patch[Type], "") | I20: =_xlfn.XLOOKUP($A$17&"-"&I$17, Data_Patch[Outlet ID], Data_Patch[Type], "") | J20: TYPE
A22: NODE5 | B22: PORT1 | C22: PORT2 | D22: PORT3 | E22: PORT4 | F22: PORT5 | G22: PORT6 | H22: PORT7 | I22: PORT8
A23: sACN | B23: =_xlfn.XLOOKUP($A$22&"-"&B$22, Data_Patch[Outlet ID], Data_Patch[Universe], "") -> 0 | C23: =_xlfn.XLOOKUP($A$22&"-"&C$22, Data_Patch[Outlet ID], Data_Patch[Universe], "") -> 0 | D23: =_xlfn.XLOOKUP($A$22&"-"&D$22, Data_Patch[Outlet ID], Data_Patch[Universe], "") -> 0 | E23: =_xlfn.XLOOKUP($A$22&"-"&E$22, Data_Patch[Outlet ID], Data_Patch[Universe], "") -> 0 | F23: =_xlfn.XLOOKUP($A$22&"-"&F$22, Data_Patch[Outlet ID], Data_Patch[Universe], "") -> 0 | G23: =_xlfn.XLOOKUP($A$22&"-"&G$22, Data_Patch[Outlet ID], Data_Patch[Universe], "") -> 0 | H23: =_xlfn.XLOOKUP($A$22&"-"&H$22, Data_Patch[Outlet ID], Data_Patch[Universe], "") -> 0 | I23: =_xlfn.XLOOKUP($A$22&"-"&I$22, Data_Patch[Outlet ID], Data_Patch[Universe], "") -> 0 | J23: UNIVERSE
A24: IP 192.168.0.xxx | B24: =_xlfn.XLOOKUP($A$22&"-"&B$22, Data_Patch[Outlet ID], Data_Patch[Cable], "") | C24: =_xlfn.XLOOKUP($A$22&"-"&C$22, Data_Patch[Outlet ID], Data_Patch[Cable], "") | D24: =_xlfn.XLOOKUP($A$22&"-"&D$22, Data_Patch[Outlet ID], Data_Patch[Cable], "") | E24: =_xlfn.XLOOKUP($A$22&"-"&E$22, Data_Patch[Outlet ID], Data_Patch[Cable], "") | F24: =_xlfn.XLOOKUP($A$22&"-"&F$22, Data_Patch[Outlet ID], Data_Patch[Cable], "") | G24: =_xlfn.XLOOKUP($A$22&"-"&G$22, Data_Patch[Outlet ID], Data_Patch[Cable], "") | H24: =_xlfn.XLOOKUP($A$22&"-"&H$22, Data_Patch[Outlet ID], Data_Patch[Cable], "") | I24: =_xlfn.XLOOKUP($A$22&"-"&I$22, Data_Patch[Outlet ID], Data_Patch[Cable], "") | J24: CABLE
B25: =_xlfn.XLOOKUP($A$22&"-"&B$22, Data_Patch[Outlet ID], Data_Patch[Type], "") | C25: =_xlfn.XLOOKUP($A$22&"-"&C$22, Data_Patch[Outlet ID], Data_Patch[Type], "") | D25: =_xlfn.XLOOKUP($A$22&"-"&D$22, Data_Patch[Outlet ID], Data_Patch[Type], "") | E25: =_xlfn.XLOOKUP($A$22&"-"&E$22, Data_Patch[Outlet ID], Data_Patch[Type], "") | F25: =_xlfn.XLOOKUP($A$22&"-"&F$22, Data_Patch[Outlet ID], Data_Patch[Type], "") | G25: =_xlfn.XLOOKUP($A$22&"-"&G$22, Data_Patch[Outlet ID], Data_Patch[Type], "") | H25: =_xlfn.XLOOKUP($A$22&"-"&H$22, Data_Patch[Outlet ID], Data_Patch[Type], "") | I25: =_xlfn.XLOOKUP($A$22&"-"&I$22, Data_Patch[Outlet ID], Data_Patch[Type], "") | J25: TYPE
Q27: PATCH BAY COLOUR
B29: 1 | C29: 2 | D29: 3 | E29: 4 | F29: 5 | G29: 6 | H29: 7 | I29: 8 | J29: 9 | K29: 10 | L29: 11 | M29: 12 | N29: 13 | O29: 14 | P29: 15
A30: Sneak Panel | B30: =_xlfn.XLOOKUP(B29, Data_Multis[Multi ID], Data_Multis[Multi Name], "") -> DSB1 | C30: =_xlfn.XLOOKUP(C29, Data_Multis[Multi ID], Data_Multis[Multi Name], "") -> SLW1 | D30: =_xlfn.XLOOKUP(D29, Data_Multis[Multi ID], Data_Multis[Multi Name], "") -> THR1 | E30: =_xlfn.XLOOKUP(E29, Data_Multis[Multi ID], Data_Multis[Multi Name], "") -> THR2 | F30: =_xlfn.XLOOKUP(F29, Data_Multis[Multi ID], Data_Multis[Multi Name], "") -> DSL1 | G30: =_xlfn.XLOOKUP(G29, Data_Multis[Multi ID], Data_Multis[Multi Name], "") -> SLWF1 | H30: =_xlfn.XLOOKUP(H29, Data_Multis[Multi ID], Data_Multis[Multi Name], "") -> SRL1 | I30: =_xlfn.XLOOKUP(I29, Data_Multis[Multi ID], Data_Multis[Multi Name], "") -> SLL1 | ... P30: =_xlfn.XLOOKUP(P29, Data_Multis[Multi ID], Data_Multis[Multi Name], "") | Q30: LABEL
A31: Line1 | B31: =_xlfn.XLOOKUP(B29, Data_Multis[Multi ID], Data_Multis[Line 1], "") -> DSB1 U1 | C31: =_xlfn.XLOOKUP(C29, Data_Multis[Multi ID], Data_Multis[Line 1], "") -> SLW1 U12 | D31: =_xlfn.XLOOKUP(D29, Data_Multis[Multi ID], Data_Multis[Line 1], "") -> THR1 U17 | E31: =_xlfn.XLOOKUP(E29, Data_Multis[Multi ID], Data_Multis[Line 1], "") -> THR5 U21 | F31: =_xlfn.XLOOKUP(F29, Data_Multis[Multi ID], Data_Multis[Line 1], "") -> DSL1 U22 | G31: =_xlfn.XLOOKUP(G29, Data_Multis[Multi ID], Data_Multis[Line 1], "") -> SLWF1 U24 | H31: =_xlfn.XLOOKUP(H29, Data_Multis[Multi ID], Data_Multis[Line 1], "") -> SRL1 U25 | I31: =_xlfn.XLOOKUP(I29, Data_Multis[Multi ID], Data_Multis[Line 1], "") -> SLL1 U29 | ... P31: =_xlfn.XLOOKUP(P29, Data_Multis[Multi ID], Data_Multis[Line 1], "")
A32: Line2 | B32: =_xlfn.XLOOKUP(B29, Data_Multis[Multi ID], Data_Multis[Line 2], "") -> DSB2 U2 | C32: =_xlfn.XLOOKUP(C29, Data_Multis[Multi ID], Data_Multis[Line 2], "") -> SLW2 U13 | D32: =_xlfn.XLOOKUP(D29, Data_Multis[Multi ID], Data_Multis[Line 2], "") -> THR2 U18 | E32: =_xlfn.XLOOKUP(E29, Data_Multis[Multi ID], Data_Multis[Line 2], "") | F32: =_xlfn.XLOOKUP(F29, Data_Multis[Multi ID], Data_Multis[Line 2], "") -> DSL2 U23 | G32: =_xlfn.XLOOKUP(G29, Data_Multis[Multi ID], Data_Multis[Line 2], "") | H32: =_xlfn.XLOOKUP(H29, Data_Multis[Multi ID], Data_Multis[Line 2], "") -> SRL2 U26 | I32: =_xlfn.XLOOKUP(I29, Data_Multis[Multi ID], Data_Multis[Line 2], "") -> SLL2 U30 | ... P32: =_xlfn.XLOOKUP(P29, Data_Multis[Multi ID], Data_Multis[Line 2], "")
A33: Line3 | B33: =_xlfn.XLOOKUP(B29, Data_Multis[Multi ID], Data_Multis[Line 3], "") | C33: =_xlfn.XLOOKUP(C29, Data_Multis[Multi ID], Data_Multis[Line 3], "") | D33: =_xlfn.XLOOKUP(D29, Data_Multis[Multi ID], Data_Multis[Line 3], "") -> THR3 U19 | E33: =_xlfn.XLOOKUP(E29, Data_Multis[Multi ID], Data_Multis[Line 3], "") | F33: =_xlfn.XLOOKUP(F29, Data_Multis[Multi ID], Data_Multis[Line 3], "") | G33: =_xlfn.XLOOKUP(G29, Data_Multis[Multi ID], Data_Multis[Line 3], "") | H33: =_xlfn.XLOOKUP(H29, Data_Multis[Multi ID], Data_Multis[Line 3], "") -> SRL3 U27 | I33: =_xlfn.XLOOKUP(I29, Data_Multis[Multi ID], Data_Multis[Line 3], "") -> SLL3 U31 | ... P33: =_xlfn.XLOOKUP(P29, Data_Multis[Multi ID], Data_Multis[Line 3], "")
A34: Line4 | B34: =_xlfn.XLOOKUP(B29, Data_Multis[Multi ID], Data_Multis[Line 4], "") | C34: =_xlfn.XLOOKUP(C29, Data_Multis[Multi ID], Data_Multis[Line 4], "") | D34: =_xlfn.XLOOKUP(D29, Data_Multis[Multi ID], Data_Multis[Line 4], "") -> THR4 U20 | E34: =_xlfn.XLOOKUP(E29, Data_Multis[Multi ID], Data_Multis[Line 4], "") | F34: =_xlfn.XLOOKUP(F29, Data_Multis[Multi ID], Data_Multis[Line 4], "") | G34: =_xlfn.XLOOKUP(G29, Data_Multis[Multi ID], Data_Multis[Line 4], "") | H34: =_xlfn.XLOOKUP(H29, Data_Multis[Multi ID], Data_Multis[Line 4], "") -> SRL4 U28 | I34: =_xlfn.XLOOKUP(I29, Data_Multis[Multi ID], Data_Multis[Line 4], "") -> SLL4 U32 | ... P34: =_xlfn.XLOOKUP(P29, Data_Multis[Multi ID], Data_Multis[Line 4], "")
A36: optiSPLIT | B36: PORT1 | C36: PORT2 | D36: PORT3 | E36: PORT4 | F36: PORT5 | G36: PORT6 | H36: PORT7 | I36: PORT8
J37: CABLE
J38: TYPE
A40: optiSPLIT | B40: PORT1 | C40: PORT2 | D40: PORT3 | E40: PORT4 | F40: PORT5 | G40: PORT6 | H40: PORT7 | I40: PORT8
J41: CABLE
J42: TYPE
A44: optiSPLIT | B44: PORT1 | C44: PORT2 | D44: PORT3 | E44: PORT4 | F44: PORT5 | G44: PORT6 | H44: PORT7 | I44: PORT8
J45: CABLE
J46: TYPE
A48: optiSPLIT | B48: PORT1 | C48: PORT2 | D48: PORT3 | E48: PORT4 | F48: PORT5 | G48: PORT6 | H48: PORT7 | I48: PORT8
J49: CABLE
J50: TYPE

Sheet NODE32
A1: NODE 32 | J1: =DATA!$G$2 -> Untitled Show | Q1: #VALUE!
A2: NODE1 | B2: PORT1 | C2: PORT2 | D2: PORT3 | E2: PORT4 | F2: PORT5 | G2: PORT6 | H2: PORT7 | I2: PORT8 | M2: Outlet Count | N2: =COUNTA(Data_Patch[Outlet ID]) -> 144
A3: sACN | B3: =_xlfn.XLOOKUP($A$2&"-"&B$2, Data_Patch[Outlet ID], Data_Patch[Universe], "") -> 1 | C3: =_xlfn.XLOOKUP($A$2&"-"&C$2, Data_Patch[Outlet ID], Data_Patch[Universe], "") -> 2 | D3: =_xlfn.XLOOKUP($A$2&"-"&D$2, Data_Patch[Outlet ID], Data_Patch[Universe], "") -> 0 | E3: =_xlfn.XLOOKUP($A$2&"-"&E$2, Data_Patch[Outlet ID], Data_Patch[Universe], "") -> 0 | F3: =_xlfn.XLOOKUP($A$2&"-"&F$2, Data_Patch[Outlet ID], Data_Patch[Universe], "") -> 12 | G3: =_xlfn.XLOOKUP($A$2&"-"&G$2, Data_Patch[Outlet ID], Data_Patch[Universe], "") -> 13 | H3: =_xlfn.XLOOKUP($A$2&"-"&H$2, Data_Patch[Outlet ID], Data_Patch[Universe], "") -> 0 | I3: =_xlfn.XLOOKUP($A$2&"-"&I$2, Data_Patch[Outlet ID], Data_Patch[Universe], "") -> 0 | J3: UNIVERSE | M3: Outlets | N3: 32
A4: IP 192.168.0.xxx | B4: =_xlfn.XLOOKUP($A$2&"-"&B$2, Data_Patch[Outlet ID], Data_Patch[Cable], "") -> DSB1 | C4: =_xlfn.XLOOKUP($A$2&"-"&C$2, Data_Patch[Outlet ID], Data_Patch[Cable], "") -> DSB2 | D4: =_xlfn.XLOOKUP($A$2&"-"&D$2, Data_Patch[Outlet ID], Data_Patch[Cable], "") | E4: =_xlfn.XLOOKUP($A$2&"-"&E$2, Data_Patch[Outlet ID], Data_Patch[Cable], "") | F4: =_xlfn.XLOOKUP($A$2&"-"&F$2, Data_Patch[Outlet ID], Data_Patch[Cable], "") -> SLW1 | G4: =_xlfn.XLOOKUP($A$2&"-"&G$2, Data_Patch[Outlet ID], Data_Patch[Cable], "") -> SLW2 | H4: =_xlfn.XLOOKUP($A$2&"-"&H$2, Data_Patch[Outlet ID], Data_Patch[Cable], "") | I4: =_xlfn.XLOOKUP($A$2&"-"&I$2, Data_Patch[Outlet ID], Data_Patch[Cable], "") | J4: CABLE
B5: =_xlfn.XLOOKUP($A$2&"-"&B$2, Data_Patch[Outlet ID], Data_Patch[Type], "") -> Sneak | C5: =_xlfn.XLOOKUP($A$2&"-"&C$2, Data_Patch[Outlet ID], Data_Patch[Type], "") -> Sneak | D5: =_xlfn.XLOOKUP($A$2&"-"&D$2, Data_Patch[Outlet ID], Data_Patch[Type], "") | E5: =_xlfn.XLOOKUP($A$2&"-"&E$2, Data_Patch[Outlet ID], Data_Patch[Type], "") | F5: =_xlfn.XLOOKUP($A$2&"-"&F$2, Data_Patch[Outlet ID], Data_Patch[Type], "") -> Sneak | G5: =_xlfn.XLOOKUP($A$2&"-"&G$2, Data_Patch[Outlet ID], Data_Patch[Type], "") -> Sneak | H5: =_xlfn.XLOOKUP($A$2&"-"&H$2, Data_Patch[Outlet ID], Data_Patch[Type], "") | I5: =_xlfn.XLOOKUP($A$2&"-"&I$2, Data_Patch[Outlet ID], Data_Patch[Type], "") | J5: TYPE
A7: NODE2 | B7: PORT1 | C7: PORT2 | D7: PORT3 | E7: PORT4 | F7: PORT5 | G7: PORT6 | H7: PORT7 | I7: PORT8
A8: sACN | B8: =_xlfn.XLOOKUP($A$7&"-"&B$7, Data_Patch[Outlet ID], Data_Patch[Universe], "") -> 0 | C8: =_xlfn.XLOOKUP($A$7&"-"&C$7, Data_Patch[Outlet ID], Data_Patch[Universe], "") -> 0 | D8: =_xlfn.XLOOKUP($A$7&"-"&D$7, Data_Patch[Outlet ID], Data_Patch[Universe], "") -> 0 | E8: =_xlfn.XLOOKUP($A$7&"-"&E$7, Data_Patch[Outlet ID], Data_Patch[Universe], "") -> 0 | F8: =_xlfn.XLOOKUP($A$7&"-"&F$7, Data_Patch[Outlet ID], Data_Patch[Universe], "") -> 0 | G8: =_xlfn.XLOOKUP($A$7&"-"&G$7, Data_Patch[Outlet ID], Data_Patch[Universe], "") -> 0 | H8: =_xlfn.XLOOKUP($A$7&"-"&H$7, Data_Patch[Outlet ID], Data_Patch[Universe], "") -> 0 | I8: =_xlfn.XLOOKUP($A$7&"-"&I$7, Data_Patch[Outlet ID], Data_Patch[Universe], "") -> 0 | J8: UNIVERSE
A9: IP 192.168.0.xxx | B9: =_xlfn.XLOOKUP($A$7&"-"&B$7, Data_Patch[Outlet ID], Data_Patch[Cable], "") | C9: =_xlfn.XLOOKUP($A$7&"-"&C$7, Data_Patch[Outlet ID], Data_Patch[Cable], "") | D9: =_xlfn.XLOOKUP($A$7&"-"&D$7, Data_Patch[Outlet ID], Data_Patch[Cable], "") | E9: =_xlfn.XLOOKUP($A$7&"-"&E$7, Data_Patch[Outlet ID], Data_Patch[Cable], "") | F9: =_xlfn.XLOOKUP($A$7&"-"&F$7, Data_Patch[Outlet ID], Data_Patch[Cable], "") | G9: =_xlfn.XLOOKUP($A$7&"-"&G$7, Data_Patch[Outlet ID], Data_Patch[Cable], "") | H9: =_xlfn.XLOOKUP($A$7&"-"&H$7, Data_Patch[Outlet ID], Data_Patch[Cable], "") | I9: =_xlfn.XLOOKUP($A$7&"-"&I$7, Data_Patch[Outlet ID], Data_Patch[Cable], "") | J9: CABLE
B10: =_xlfn.XLOOKUP($A$7&"-"&B$7, Data_Patch[Outlet ID], Data_Patch[Type], "") | C10: =_xlfn.XLOOKUP($A$7&"-"&C$7, Data_Patch[Outlet ID], Data_Patch[Type], "") | D10: =_xlfn.XLOOKUP($A$7&"-"&D$7, Data_Patch[Outlet ID], Data_Patch[Type], "") | E10: =_xlfn.XLOOKUP($A$7&"-"&E$7, Data_Patch[Outlet ID], Data_Patch[Type], "") | F10: =_xlfn.XLOOKUP($A$7&"-"&F$7, Data_Patch[Outlet ID], Data_Patch[Type], "") | G10: =_xlfn.XLOOKUP($A$7&"-"&G$7, Data_Patch[Outlet ID], Data_Patch[Type], "") | H10: =_xlfn.XLOOKUP($A$7&"-"&H$7, Data_Patch[Outlet ID], Data_Patch[Type], "") | I10: =_xlfn.XLOOKUP($A$7&"-"&I$7, Data_Patch[Outlet ID], Data_Patch[Type], "") | J10: TYPE
A12: NODE3 | B12: PORT1 | C12: PORT2 | D12: PORT3 | E12: PORT4 | F12: PORT5 | G12: PORT6 | H12: PORT7 | I12: PORT8
A13: sACN | B13: =_xlfn.XLOOKUP($A$12&"-"&B$12, Data_Patch[Outlet ID], Data_Patch[Universe], "") -> 0 | C13: =_xlfn.XLOOKUP($A$12&"-"&C$12, Data_Patch[Outlet ID], Data_Patch[Universe], "") -> 0 | D13: =_xlfn.XLOOKUP($A$12&"-"&D$12, Data_Patch[Outlet ID], Data_Patch[Universe], "") -> 0 | E13: =_xlfn.XLOOKUP($A$12&"-"&E$12, Data_Patch[Outlet ID], Data_Patch[Universe], "") -> 0 | F13: =_xlfn.XLOOKUP($A$12&"-"&F$12, Data_Patch[Outlet ID], Data_Patch[Universe], "") -> 0 | G13: =_xlfn.XLOOKUP($A$12&"-"&G$12, Data_Patch[Outlet ID], Data_Patch[Universe], "") -> 0 | H13: =_xlfn.XLOOKUP($A$12&"-"&H$12, Data_Patch[Outlet ID], Data_Patch[Universe], "") -> 0 | I13: =_xlfn.XLOOKUP($A$12&"-"&I$12, Data_Patch[Outlet ID], Data_Patch[Universe], "") -> 0 | J13: UNIVERSE
A14: IP 192.168.0.xxx | B14: =_xlfn.XLOOKUP($A$12&"-"&B$12, Data_Patch[Outlet ID], Data_Patch[Cable], "") | C14: =_xlfn.XLOOKUP($A$12&"-"&C$12, Data_Patch[Outlet ID], Data_Patch[Cable], "") | D14: =_xlfn.XLOOKUP($A$12&"-"&D$12, Data_Patch[Outlet ID], Data_Patch[Cable], "") | E14: =_xlfn.XLOOKUP($A$12&"-"&E$12, Data_Patch[Outlet ID], Data_Patch[Cable], "") | F14: =_xlfn.XLOOKUP($A$12&"-"&F$12, Data_Patch[Outlet ID], Data_Patch[Cable], "") | G14: =_xlfn.XLOOKUP($A$12&"-"&G$12, Data_Patch[Outlet ID], Data_Patch[Cable], "") | H14: =_xlfn.XLOOKUP($A$12&"-"&H$12, Data_Patch[Outlet ID], Data_Patch[Cable], "") | I14: =_xlfn.XLOOKUP($A$12&"-"&I$12, Data_Patch[Outlet ID], Data_Patch[Cable], "") | J14: CABLE
B15: =_xlfn.XLOOKUP($A$12&"-"&B$12, Data_Patch[Outlet ID], Data_Patch[Type], "") | C15: =_xlfn.XLOOKUP($A$12&"-"&C$12, Data_Patch[Outlet ID], Data_Patch[Type], "") | D15: =_xlfn.XLOOKUP($A$12&"-"&D$12, Data_Patch[Outlet ID], Data_Patch[Type], "") | E15: =_xlfn.XLOOKUP($A$12&"-"&E$12, Data_Patch[Outlet ID], Data_Patch[Type], "") | F15: =_xlfn.XLOOKUP($A$12&"-"&F$12, Data_Patch[Outlet ID], Data_Patch[Type], "") | G15: =_xlfn.XLOOKUP($A$12&"-"&G$12, Data_Patch[Outlet ID], Data_Patch[Type], "") | H15: =_xlfn.XLOOKUP($A$12&"-"&H$12, Data_Patch[Outlet ID], Data_Patch[Type], "") | I15: =_xlfn.XLOOKUP($A$12&"-"&I$12, Data_Patch[Outlet ID], Data_Patch[Type], "") | J15: TYPE
A17: NODE4 | B17: PORT1 | C17: PORT2 | D17: PORT3 | E17: PORT4 | F17: PORT5 | G17: PORT6 | H17: PORT7 | I17: PORT8
A18: sACN | B18: =_xlfn.XLOOKUP($A$17&"-"&B$17, Data_Patch[Outlet ID], Data_Patch[Universe], "") -> 0 | C18: =_xlfn.XLOOKUP($A$17&"-"&C$17, Data_Patch[Outlet ID], Data_Patch[Universe], "") -> 0 | D18: =_xlfn.XLOOKUP($A$17&"-"&D$17, Data_Patch[Outlet ID], Data_Patch[Universe], "") -> 0 | E18: =_xlfn.XLOOKUP($A$17&"-"&E$17, Data_Patch[Outlet ID], Data_Patch[Universe], "") -> 0 | F18: =_xlfn.XLOOKUP($A$17&"-"&F$17, Data_Patch[Outlet ID], Data_Patch[Universe], "") -> 0 | G18: =_xlfn.XLOOKUP($A$17&"-"&G$17, Data_Patch[Outlet ID], Data_Patch[Universe], "") -> 0 | H18: =_xlfn.XLOOKUP($A$17&"-"&H$17, Data_Patch[Outlet ID], Data_Patch[Universe], "") -> 0 | I18: =_xlfn.XLOOKUP($A$17&"-"&I$17, Data_Patch[Outlet ID], Data_Patch[Universe], "") -> 0 | J18: UNIVERSE
A19: IP 192.168.0.xxx | B19: =_xlfn.XLOOKUP($A$17&"-"&B$17, Data_Patch[Outlet ID], Data_Patch[Cable], "") | C19: =_xlfn.XLOOKUP($A$17&"-"&C$17, Data_Patch[Outlet ID], Data_Patch[Cable], "") | D19: =_xlfn.XLOOKUP($A$17&"-"&D$17, Data_Patch[Outlet ID], Data_Patch[Cable], "") | E19: =_xlfn.XLOOKUP($A$17&"-"&E$17, Data_Patch[Outlet ID], Data_Patch[Cable], "") | F19: =_xlfn.XLOOKUP($A$17&"-"&F$17, Data_Patch[Outlet ID], Data_Patch[Cable], "") | G19: =_xlfn.XLOOKUP($A$17&"-"&G$17, Data_Patch[Outlet ID], Data_Patch[Cable], "") | H19: =_xlfn.XLOOKUP($A$17&"-"&H$17, Data_Patch[Outlet ID], Data_Patch[Cable], "") | I19: =_xlfn.XLOOKUP($A$17&"-"&I$17, Data_Patch[Outlet ID], Data_Patch[Cable], "") | J19: CABLE
B20: =_xlfn.XLOOKUP($A$17&"-"&B$17, Data_Patch[Outlet ID], Data_Patch[Type], "") | C20: =_xlfn.XLOOKUP($A$17&"-"&C$17, Data_Patch[Outlet ID], Data_Patch[Type], "") | D20: =_xlfn.XLOOKUP($A$17&"-"&D$17, Data_Patch[Outlet ID], Data_Patch[Type], "") | E20: =_xlfn.XLOOKUP($A$17&"-"&E$17, Data_Patch[Outlet ID], Data_Patch[Type], "") | F20: =_xlfn.XLOOKUP($A$17&"-"&F$17, Data_Patch[Outlet ID], Data_Patch[Type], "") | G20: =_xlfn.XLOOKUP($A$17&"-"&G$17, Data_Patch[Outlet ID], Data_Patch[Type], "") | H20: =_xlfn.XLOOKUP($A$17&"-"&H$17, Data_Patch[Outlet ID], Data_Patch[Type], "") | I20: =_xlfn.XLOOKUP($A$17&"-"&I$17, Data_Patch[Outlet ID], Data_Patch[Type], "") | J20: TYPE
B24: 1 | C24: 2 | D24: 3 | E24: 4 | F24: 5 | G24: 6 | H24: 7 | I24: 8
A25: Sneak Panel | B25: =_xlfn.XLOOKUP(B24, Data_Multis[Multi ID], Data_Multis[Multi Name], "") -> DSB1 | C25: =_xlfn.XLOOKUP(C24, Data_Multis[Multi ID], Data_Multis[Multi Name], "") -> SLW1 | D25: =_xlfn.XLOOKUP(D24, Data_Multis[Multi ID], Data_Multis[Multi Name], "") -> THR1 | E25: =_xlfn.XLOOKUP(E24, Data_Multis[Multi ID], Data_Multis[Multi Name], "") -> THR2 | F25: =_xlfn.XLOOKUP(F24, Data_Multis[Multi ID], Data_Multis[Multi Name], "") -> DSL1 | G25: =_xlfn.XLOOKUP(G24, Data_Multis[Multi ID], Data_Multis[Multi Name], "") -> SLWF1 | H25: =_xlfn.XLOOKUP(H24, Data_Multis[Multi ID], Data_Multis[Multi Name], "") -> SRL1 | I25: =_xlfn.XLOOKUP(I24, Data_Multis[Multi ID], Data_Multis[Multi Name], "") -> SLL1
A26: Line1 | B26: =_xlfn.XLOOKUP(B24, Data_Multis[Multi ID], Data_Multis[Line 1], "") -> DSB1 U1 | C26: =_xlfn.XLOOKUP(C24, Data_Multis[Multi ID], Data_Multis[Line 1], "") -> SLW1 U12 | D26: =_xlfn.XLOOKUP(D24, Data_Multis[Multi ID], Data_Multis[Line 1], "") -> THR1 U17 | E26: =_xlfn.XLOOKUP(E24, Data_Multis[Multi ID], Data_Multis[Line 1], "") -> THR5 U21 | F26: =_xlfn.XLOOKUP(F24, Data_Multis[Multi ID], Data_Multis[Line 1], "") -> DSL1 U22 | G26: =_xlfn.XLOOKUP(G24, Data_Multis[Multi ID], Data_Multis[Line 1], "") -> SLWF1 U24 | H26: =_xlfn.XLOOKUP(H24, Data_Multis[Multi ID], Data_Multis[Line 1], "") -> SRL1 U25 | I26: =_xlfn.XLOOKUP(I24, Data_Multis[Multi ID], Data_Multis[Line 1], "") -> SLL1 U29
A27: Line2 | B27: =_xlfn.XLOOKUP(B24, Data_Multis[Multi ID], Data_Multis[Line 2], "") -> DSB2 U2 | C27: =_xlfn.XLOOKUP(C24, Data_Multis[Multi ID], Data_Multis[Line 2], "") -> SLW2 U13 | D27: =_xlfn.XLOOKUP(D24, Data_Multis[Multi ID], Data_Multis[Line 2], "") -> THR2 U18 | E27: =_xlfn.XLOOKUP(E24, Data_Multis[Multi ID], Data_Multis[Line 2], "") | F27: =_xlfn.XLOOKUP(F24, Data_Multis[Multi ID], Data_Multis[Line 2], "") -> DSL2 U23 | G27: =_xlfn.XLOOKUP(G24, Data_Multis[Multi ID], Data_Multis[Line 2], "") | H27: =_xlfn.XLOOKUP(H24, Data_Multis[Multi ID], Data_Multis[Line 2], "") -> SRL2 U26 | I27: =_xlfn.XLOOKUP(I24, Data_Multis[Multi ID], Data_Multis[Line 2], "") -> SLL2 U30
A28: Line3 | B28: =_xlfn.XLOOKUP(B24, Data_Multis[Multi ID], Data_Multis[Line 3], "") | C28: =_xlfn.XLOOKUP(C24, Data_Multis[Multi ID], Data_Multis[Line 3], "") | D28: =_xlfn.XLOOKUP(D24, Data_Multis[Multi ID], Data_Multis[Line 3], "") -> THR3 U19 | E28: =_xlfn.XLOOKUP(E24, Data_Multis[Multi ID], Data_Multis[Line 3], "") | F28: =_xlfn.XLOOKUP(F24, Data_Multis[Multi ID], Data_Multis[Line 3], "") | G28: =_xlfn.XLOOKUP(G24, Data_Multis[Multi ID], Data_Multis[Line 3], "") | H28: =_xlfn.XLOOKUP(H24, Data_Multis[Multi ID], Data_Multis[Line 3], "") -> SRL3 U27 | I28: =_xlfn.XLOOKUP(I24, Data_Multis[Multi ID], Data_Multis[Line 3], "") -> SLL3 U31
A29: Line4 | B29: =_xlfn.XLOOKUP(B24, Data_Multis[Multi ID], Data_Multis[Line 4], "") | C29: =_xlfn.XLOOKUP(C24, Data_Multis[Multi ID], Data_Multis[Line 4], "") | D29: =_xlfn.XLOOKUP(D24, Data_Multis[Multi ID], Data_Multis[Line 4], "") -> THR4 U20 | E29: =_xlfn.XLOOKUP(E24, Data_Multis[Multi ID], Data_Multis[Line 4], "") | F29: =_xlfn.XLOOKUP(F24, Data_Multis[Multi ID], Data_Multis[Line 4], "") | G29: =_xlfn.XLOOKUP(G24, Data_Multis[Multi ID], Data_Multis[Line 4], "") | H29: =_xlfn.XLOOKUP(H24, Data_Multis[Multi ID], Data_Multis[Line 4], "") -> SRL4 U28 | I29: =_xlfn.XLOOKUP(I24, Data_Multis[Multi ID], Data_Multis[Line 4], "") -> SLL4 U32
A31: optiSPLIT | B31: PORT1 | C31: PORT2 | D31: PORT3 | E31: PORT4 | F31: PORT5 | G31: PORT6 | H31: PORT7 | I31: PORT8
J32: CABLE
J33: TYPE
A35: optiSPLIT | B35: PORT1 | C35: PORT2 | D35: PORT3 | E35: PORT4 | F35: PORT5 | G35: PORT6 | H35: PORT7 | I35: PORT8
J36: CABLE
J37: TYPE
A39: optiSPLIT | B39: PORT1 | C39: PORT2 | D39: PORT3 | E39: PORT4 | F39: PORT5 | G39: PORT6 | H39: PORT7 | I39: PORT8
J40: CABLE
J41: TYPE
A43: optiSPLIT | B43: PORT1 | C43: PORT2 | D43: PORT3 | E43: PORT4 | F43: PORT5 | G43: PORT6 | H43: PORT7 | I43: PORT8
J44: CABLE
J45: TYPE

Sheet NODE24
A1: NODE 24 | J1: =DATA!$G$2 -> Untitled Show | Q1: #VALUE!
A2: NODE1 | B2: PORT1 | C2: PORT2 | D2: PORT3 | E2: PORT4 | F2: PORT5 | G2: PORT6 | H2: PORT7 | I2: PORT8 | M2: Outlet Count | N2: =COUNTA(Data_Patch[Outlet ID]) -> 144
A3: sACN | B3: =_xlfn.XLOOKUP($A$2&"-"&B$2, Data_Patch[Outlet ID], Data_Patch[Universe], "") -> 1 | C3: =_xlfn.XLOOKUP($A$2&"-"&C$2, Data_Patch[Outlet ID], Data_Patch[Universe], "") -> 2 | D3: =_xlfn.XLOOKUP($A$2&"-"&D$2, Data_Patch[Outlet ID], Data_Patch[Universe], "") -> 0 | E3: =_xlfn.XLOOKUP($A$2&"-"&E$2, Data_Patch[Outlet ID], Data_Patch[Universe], "") -> 0 | F3: =_xlfn.XLOOKUP($A$2&"-"&F$2, Data_Patch[Outlet ID], Data_Patch[Universe], "") -> 12 | G3: =_xlfn.XLOOKUP($A$2&"-"&G$2, Data_Patch[Outlet ID], Data_Patch[Universe], "") -> 13 | H3: =_xlfn.XLOOKUP($A$2&"-"&H$2, Data_Patch[Outlet ID], Data_Patch[Universe], "") -> 0 | I3: =_xlfn.XLOOKUP($A$2&"-"&I$2, Data_Patch[Outlet ID], Data_Patch[Universe], "") -> 0 | J3: UNIVERSE | M3: Outlets | N3: 24
A4: IP 192.168.0.xxx | B4: =_xlfn.XLOOKUP($A$2&"-"&B$2, Data_Patch[Outlet ID], Data_Patch[Cable], "") -> DSB1 | C4: =_xlfn.XLOOKUP($A$2&"-"&C$2, Data_Patch[Outlet ID], Data_Patch[Cable], "") -> DSB2 | D4: =_xlfn.XLOOKUP($A$2&"-"&D$2, Data_Patch[Outlet ID], Data_Patch[Cable], "") | E4: =_xlfn.XLOOKUP($A$2&"-"&E$2, Data_Patch[Outlet ID], Data_Patch[Cable], "") | F4: =_xlfn.XLOOKUP($A$2&"-"&F$2, Data_Patch[Outlet ID], Data_Patch[Cable], "") -> SLW1 | G4: =_xlfn.XLOOKUP($A$2&"-"&G$2, Data_Patch[Outlet ID], Data_Patch[Cable], "") -> SLW2 | H4: =_xlfn.XLOOKUP($A$2&"-"&H$2, Data_Patch[Outlet ID], Data_Patch[Cable], "") | I4: =_xlfn.XLOOKUP($A$2&"-"&I$2, Data_Patch[Outlet ID], Data_Patch[Cable], "") | J4: CABLE
B5: =_xlfn.XLOOKUP($A$2&"-"&B$2, Data_Patch[Outlet ID], Data_Patch[Type], "") -> Sneak | C5: =_xlfn.XLOOKUP($A$2&"-"&C$2, Data_Patch[Outlet ID], Data_Patch[Type], "") -> Sneak | D5: =_xlfn.XLOOKUP($A$2&"-"&D$2, Data_Patch[Outlet ID], Data_Patch[Type], "") | E5: =_xlfn.XLOOKUP($A$2&"-"&E$2, Data_Patch[Outlet ID], Data_Patch[Type], "") | F5: =_xlfn.XLOOKUP($A$2&"-"&F$2, Data_Patch[Outlet ID], Data_Patch[Type], "") -> Sneak | G5: =_xlfn.XLOOKUP($A$2&"-"&G$2, Data_Patch[Outlet ID], Data_Patch[Type], "") -> Sneak | H5: =_xlfn.XLOOKUP($A$2&"-"&H$2, Data_Patch[Outlet ID], Data_Patch[Type], "") | I5: =_xlfn.XLOOKUP($A$2&"-"&I$2, Data_Patch[Outlet ID], Data_Patch[Type], "") | J5: TYPE
A7: NODE2 | B7: PORT1 | C7: PORT2 | D7: PORT3 | E7: PORT4 | F7: PORT5 | G7: PORT6 | H7: PORT7 | I7: PORT8
A8: sACN | B8: =_xlfn.XLOOKUP($A$7&"-"&B$7, Data_Patch[Outlet ID], Data_Patch[Universe], "") -> 0 | C8: =_xlfn.XLOOKUP($A$7&"-"&C$7, Data_Patch[Outlet ID], Data_Patch[Universe], "") -> 0 | D8: =_xlfn.XLOOKUP($A$7&"-"&D$7, Data_Patch[Outlet ID], Data_Patch[Universe], "") -> 0 | E8: =_xlfn.XLOOKUP($A$7&"-"&E$7, Data_Patch[Outlet ID], Data_Patch[Universe], "") -> 0 | F8: =_xlfn.XLOOKUP($A$7&"-"&F$7, Data_Patch[Outlet ID], Data_Patch[Universe], "") -> 0 | G8: =_xlfn.XLOOKUP($A$7&"-"&G$7, Data_Patch[Outlet ID], Data_Patch[Universe], "") -> 0 | H8: =_xlfn.XLOOKUP($A$7&"-"&H$7, Data_Patch[Outlet ID], Data_Patch[Universe], "") -> 0 | I8: =_xlfn.XLOOKUP($A$7&"-"&I$7, Data_Patch[Outlet ID], Data_Patch[Universe], "") -> 0 | J8: UNIVERSE
A9: IP 192.168.0.xxx | B9: =_xlfn.XLOOKUP($A$7&"-"&B$7, Data_Patch[Outlet ID], Data_Patch[Cable], "") | C9: =_xlfn.XLOOKUP($A$7&"-"&C$7, Data_Patch[Outlet ID], Data_Patch[Cable], "") | D9: =_xlfn.XLOOKUP($A$7&"-"&D$7, Data_Patch[Outlet ID], Data_Patch[Cable], "") | E9: =_xlfn.XLOOKUP($A$7&"-"&E$7, Data_Patch[Outlet ID], Data_Patch[Cable], "") | F9: =_xlfn.XLOOKUP($A$7&"-"&F$7, Data_Patch[Outlet ID], Data_Patch[Cable], "") | G9: =_xlfn.XLOOKUP($A$7&"-"&G$7, Data_Patch[Outlet ID], Data_Patch[Cable], "") | H9: =_xlfn.XLOOKUP($A$7&"-"&H$7, Data_Patch[Outlet ID], Data_Patch[Cable], "") | I9: =_xlfn.XLOOKUP($A$7&"-"&I$7, Data_Patch[Outlet ID], Data_Patch[Cable], "") | J9: CABLE
B10: =_xlfn.XLOOKUP($A$7&"-"&B$7, Data_Patch[Outlet ID], Data_Patch[Type], "") | C10: =_xlfn.XLOOKUP($A$7&"-"&C$7, Data_Patch[Outlet ID], Data_Patch[Type], "") | D10: =_xlfn.XLOOKUP($A$7&"-"&D$7, Data_Patch[Outlet ID], Data_Patch[Type], "") | E10: =_xlfn.XLOOKUP($A$7&"-"&E$7, Data_Patch[Outlet ID], Data_Patch[Type], "") | F10: =_xlfn.XLOOKUP($A$7&"-"&F$7, Data_Patch[Outlet ID], Data_Patch[Type], "") | G10: =_xlfn.XLOOKUP($A$7&"-"&G$7, Data_Patch[Outlet ID], Data_Patch[Type], "") | H10: =_xlfn.XLOOKUP($A$7&"-"&H$7, Data_Patch[Outlet ID], Data_Patch[Type], "") | I10: =_xlfn.XLOOKUP($A$7&"-"&I$7, Data_Patch[Outlet ID], Data_Patch[Type], "") | J10: TYPE
A12: NODE3 | B12: PORT1 | C12: PORT2 | D12: PORT3 | E12: PORT4 | F12: PORT5 | G12: PORT6 | H12: PORT7 | I12: PORT8
A13: sACN | B13: =_xlfn.XLOOKUP($A$12&"-"&B$12, Data_Patch[Outlet ID], Data_Patch[Universe], "") -> 0 | C13: =_xlfn.XLOOKUP($A$12&"-"&C$12, Data_Patch[Outlet ID], Data_Patch[Universe], "") -> 0 | D13: =_xlfn.XLOOKUP($A$12&"-"&D$12, Data_Patch[Outlet ID], Data_Patch[Universe], "") -> 0 | E13: =_xlfn.XLOOKUP($A$12&"-"&E$12, Data_Patch[Outlet ID], Data_Patch[Universe], "") -> 0 | F13: =_xlfn.XLOOKUP($A$12&"-"&F$12, Data_Patch[Outlet ID], Data_Patch[Universe], "") -> 0 | G13: =_xlfn.XLOOKUP($A$12&"-"&G$12, Data_Patch[Outlet ID], Data_Patch[Universe], "") -> 0 | H13: =_xlfn.XLOOKUP($A$12&"-"&H$12, Data_Patch[Outlet ID], Data_Patch[Universe], "") -> 0 | I13: =_xlfn.XLOOKUP($A$12&"-"&I$12, Data_Patch[Outlet ID], Data_Patch[Universe], "") -> 0 | J13: UNIVERSE
A14: IP 192.168.0.xxx | B14: =_xlfn.XLOOKUP($A$12&"-"&B$12, Data_Patch[Outlet ID], Data_Patch[Cable], "") | C14: =_xlfn.XLOOKUP($A$12&"-"&C$12, Data_Patch[Outlet ID], Data_Patch[Cable], "") | D14: =_xlfn.XLOOKUP($A$12&"-"&D$12, Data_Patch[Outlet ID], Data_Patch[Cable], "") | E14: =_xlfn.XLOOKUP($A$12&"-"&E$12, Data_Patch[Outlet ID], Data_Patch[Cable], "") | F14: =_xlfn.XLOOKUP($A$12&"-"&F$12, Data_Patch[Outlet ID], Data_Patch[Cable], "") | G14: =_xlfn.XLOOKUP($A$12&"-"&G$12, Data_Patch[Outlet ID], Data_Patch[Cable], "") | H14: =_xlfn.XLOOKUP($A$12&"-"&H$12, Data_Patch[Outlet ID], Data_Patch[Cable], "") | I14: =_xlfn.XLOOKUP($A$12&"-"&I$12, Data_Patch[Outlet ID], Data_Patch[Cable], "") | J14: CABLE
B15: =_xlfn.XLOOKUP($A$12&"-"&B$12, Data_Patch[Outlet ID], Data_Patch[Type], "") | C15: =_xlfn.XLOOKUP($A$12&"-"&C$12, Data_Patch[Outlet ID], Data_Patch[Type], "") | D15: =_xlfn.XLOOKUP($A$12&"-"&D$12, Data_Patch[Outlet ID], Data_Patch[Type], "") | E15: =_xlfn.XLOOKUP($A$12&"-"&E$12, Data_Patch[Outlet ID], Data_Patch[Type], "") | F15: =_xlfn.XLOOKUP($A$12&"-"&F$12, Data_Patch[Outlet ID], Data_Patch[Type], "") | G15: =_xlfn.XLOOKUP($A$12&"-"&G$12, Data_Patch[Outlet ID], Data_Patch[Type], "") | H15: =_xlfn.XLOOKUP($A$12&"-"&H$12, Data_Patch[Outlet ID], Data_Patch[Type], "") | I15: =_xlfn.XLOOKUP($A$12&"-"&I$12, Data_Patch[Outlet ID], Data_Patch[Type], "") | J15: TYPE
B19: 1 | C19: 2 | D19: 3 | E19: 4 | F19: 5 | G19: 6 | H19: 7 | I19: 8
A20: Sneak Panel | B20: =_xlfn.XLOOKUP(B19, Data_Multis[Multi ID], Data_Multis[Multi Name], "") -> DSB1 | C20: =_xlfn.XLOOKUP(C19, Data_Multis[Multi ID], Data_Multis[Multi Name], "") -> SLW1 | D20: =_xlfn.XLOOKUP(D19, Data_Multis[Multi ID], Data_Multis[Multi Name], "") -> THR1 | E20: =_xlfn.XLOOKUP(E19, Data_Multis[Multi ID], Data_Multis[Multi Name], "") -> THR2 | F20: =_xlfn.XLOOKUP(F19, Data_Multis[Multi ID], Data_Multis[Multi Name], "") -> DSL1 | G20: =_xlfn.XLOOKUP(G19, Data_Multis[Multi ID], Data_Multis[Multi Name], "") -> SLWF1 | H20: =_xlfn.XLOOKUP(H19, Data_Multis[Multi ID], Data_Multis[Multi Name], "") -> SRL1 | I20: =_xlfn.XLOOKUP(I19, Data_Multis[Multi ID], Data_Multis[Multi Name], "") -> SLL1
A21: Line1 | B21: =_xlfn.XLOOKUP(B19, Data_Multis[Multi ID], Data_Multis[Line 1], "") -> DSB1 U1 | C21: =_xlfn.XLOOKUP(C19, Data_Multis[Multi ID], Data_Multis[Line 1], "") -> SLW1 U12 | D21: =_xlfn.XLOOKUP(D19, Data_Multis[Multi ID], Data_Multis[Line 1], "") -> THR1 U17 | E21: =_xlfn.XLOOKUP(E19, Data_Multis[Multi ID], Data_Multis[Line 1], "") -> THR5 U21 | F21: =_xlfn.XLOOKUP(F19, Data_Multis[Multi ID], Data_Multis[Line 1], "") -> DSL1 U22 | G21: =_xlfn.XLOOKUP(G19, Data_Multis[Multi ID], Data_Multis[Line 1], "") -> SLWF1 U24 | H21: =_xlfn.XLOOKUP(H19, Data_Multis[Multi ID], Data_Multis[Line 1], "") -> SRL1 U25 | I21: =_xlfn.XLOOKUP(I19, Data_Multis[Multi ID], Data_Multis[Line 1], "") -> SLL1 U29
A22: Line2 | B22: =_xlfn.XLOOKUP(B19, Data_Multis[Multi ID], Data_Multis[Line 2], "") -> DSB2 U2 | C22: =_xlfn.XLOOKUP(C19, Data_Multis[Multi ID], Data_Multis[Line 2], "") -> SLW2 U13 | D22: =_xlfn.XLOOKUP(D19, Data_Multis[Multi ID], Data_Multis[Line 2], "") -> THR2 U18 | E22: =_xlfn.XLOOKUP(E19, Data_Multis[Multi ID], Data_Multis[Line 2], "") | F22: =_xlfn.XLOOKUP(F19, Data_Multis[Multi ID], Data_Multis[Line 2], "") -> DSL2 U23 | G22: =_xlfn.XLOOKUP(G19, Data_Multis[Multi ID], Data_Multis[Line 2], "") | H22: =_xlfn.XLOOKUP(H19, Data_Multis[Multi ID], Data_Multis[Line 2], "") -> SRL2 U26 | I22: =_xlfn.XLOOKUP(I19, Data_Multis[Multi ID], Data_Multis[Line 2], "") -> SLL2 U30
A23: Line3 | B23: =_xlfn.XLOOKUP(B19, Data_Multis[Multi ID], Data_Multis[Line 3], "") | C23: =_xlfn.XLOOKUP(C19, Data_Multis[Multi ID], Data_Multis[Line 3], "") | D23: =_xlfn.XLOOKUP(D19, Data_Multis[Multi ID], Data_Multis[Line 3], "") -> THR3 U19 | E23: =_xlfn.XLOOKUP(E19, Data_Multis[Multi ID], Data_Multis[Line 3], "") | F23: =_xlfn.XLOOKUP(F19, Data_Multis[Multi ID], Data_Multis[Line 3], "") | G23: =_xlfn.XLOOKUP(G19, Data_Multis[Multi ID], Data_Multis[Line 3], "") | H23: =_xlfn.XLOOKUP(H19, Data_Multis[Multi ID], Data_Multis[Line 3], "") -> SRL3 U27 | I23: =_xlfn.XLOOKUP(I19, Data_Multis[Multi ID], Data_Multis[Line 3], "") -> SLL3 U31
A24: Line4 | B24: =_xlfn.XLOOKUP(B19, Data_Multis[Multi ID], Data_Multis[Line 4], "") | C24: =_xlfn.XLOOKUP(C19, Data_Multis[Multi ID], Data_Multis[Line 4], "") | D24: =_xlfn.XLOOKUP(D19, Data_Multis[Multi ID], Data_Multis[Line 4], "") -> THR4 U20 | E24: =_xlfn.XLOOKUP(E19, Data_Multis[Multi ID], Data_Multis[Line 4], "") | F24: =_xlfn.XLOOKUP(F19, Data_Multis[Multi ID], Data_Multis[Line 4], "") | G24: =_xlfn.XLOOKUP(G19, Data_Multis[Multi ID], Data_Multis[Line 4], "") | H24: =_xlfn.XLOOKUP(H19, Data_Multis[Multi ID], Data_Multis[Line 4], "") -> SRL4 U28 | I24: =_xlfn.XLOOKUP(I19, Data_Multis[Multi ID], Data_Multis[Line 4], "") -> SLL4 U32
A26: optiSPLIT | B26: PORT1 | C26: PORT2 | D26: PORT3 | E26: PORT4 | F26: PORT5 | G26: PORT6 | H26: PORT7 | I26: PORT8
J27: CABLE
J28: TYPE
A30: optiSPLIT | B30: PORT1 | C30: PORT2 | D30: PORT3 | E30: PORT4 | F30: PORT5 | G30: PORT6 | H30: PORT7 | I30: PORT8
J31: CABLE
J32: TYPE
A34: optiSPLIT | B34: PORT1 | C34: PORT2 | D34: PORT3 | E34: PORT4 | F34: PORT5 | G34: PORT6 | H34: PORT7 | I34: PORT8
J35: CABLE
J36: TYPE
A38: optiSPLIT | B38: PORT1 | C38: PORT2 | D38: PORT3 | E38: PORT4 | F38: PORT5 | G38: PORT6 | H38: PORT7 | I38: PORT8
J39: CABLE
J40: TYPE

Sheet NODE16
A1: NODE 16 | J1: =DATA!$G$2 -> Untitled Show | Q1: #VALUE!
A2: NODE1 | B2: PORT1 | C2: PORT2 | D2: PORT3 | E2: PORT4 | F2: PORT5 | G2: PORT6 | H2: PORT7 | I2: PORT8 | M2: Outlet Count | N2: =COUNTA(Data_Patch[Outlet ID]) -> 144
A3: sACN | B3: =_xlfn.XLOOKUP($A$2&"-"&B$2, Data_Patch[Outlet ID], Data_Patch[Universe], "") -> 1 | C3: =_xlfn.XLOOKUP($A$2&"-"&C$2, Data_Patch[Outlet ID], Data_Patch[Universe], "") -> 2 | D3: =_xlfn.XLOOKUP($A$2&"-"&D$2, Data_Patch[Outlet ID], Data_Patch[Universe], "") -> 0 | E3: =_xlfn.XLOOKUP($A$2&"-"&E$2, Data_Patch[Outlet ID], Data_Patch[Universe], "") -> 0 | F3: =_xlfn.XLOOKUP($A$2&"-"&F$2, Data_Patch[Outlet ID], Data_Patch[Universe], "") -> 12 | G3: =_xlfn.XLOOKUP($A$2&"-"&G$2, Data_Patch[Outlet ID], Data_Patch[Universe], "") -> 13 | H3: =_xlfn.XLOOKUP($A$2&"-"&H$2, Data_Patch[Outlet ID], Data_Patch[Universe], "") -> 0 | I3: =_xlfn.XLOOKUP($A$2&"-"&I$2, Data_Patch[Outlet ID], Data_Patch[Universe], "") -> 0 | J3: UNIVERSE | M3: Outlets | N3: 16
A4: IP 192.168.0.xxx | B4: =_xlfn.XLOOKUP($A$2&"-"&B$2, Data_Patch[Outlet ID], Data_Patch[Cable], "") -> DSB1 | C4: =_xlfn.XLOOKUP($A$2&"-"&C$2, Data_Patch[Outlet ID], Data_Patch[Cable], "") -> DSB2 | D4: =_xlfn.XLOOKUP($A$2&"-"&D$2, Data_Patch[Outlet ID], Data_Patch[Cable], "") | E4: =_xlfn.XLOOKUP($A$2&"-"&E$2, Data_Patch[Outlet ID], Data_Patch[Cable], "") | F4: =_xlfn.XLOOKUP($A$2&"-"&F$2, Data_Patch[Outlet ID], Data_Patch[Cable], "") -> SLW1 | G4: =_xlfn.XLOOKUP($A$2&"-"&G$2, Data_Patch[Outlet ID], Data_Patch[Cable], "") -> SLW2 | H4: =_xlfn.XLOOKUP($A$2&"-"&H$2, Data_Patch[Outlet ID], Data_Patch[Cable], "") | I4: =_xlfn.XLOOKUP($A$2&"-"&I$2, Data_Patch[Outlet ID], Data_Patch[Cable], "") | J4: CABLE
B5: =_xlfn.XLOOKUP($A$2&"-"&B$2, Data_Patch[Outlet ID], Data_Patch[Type], "") -> Sneak | C5: =_xlfn.XLOOKUP($A$2&"-"&C$2, Data_Patch[Outlet ID], Data_Patch[Type], "") -> Sneak | D5: =_xlfn.XLOOKUP($A$2&"-"&D$2, Data_Patch[Outlet ID], Data_Patch[Type], "") | E5: =_xlfn.XLOOKUP($A$2&"-"&E$2, Data_Patch[Outlet ID], Data_Patch[Type], "") | F5: =_xlfn.XLOOKUP($A$2&"-"&F$2, Data_Patch[Outlet ID], Data_Patch[Type], "") -> Sneak | G5: =_xlfn.XLOOKUP($A$2&"-"&G$2, Data_Patch[Outlet ID], Data_Patch[Type], "") -> Sneak | H5: =_xlfn.XLOOKUP($A$2&"-"&H$2, Data_Patch[Outlet ID], Data_Patch[Type], "") | I5: =_xlfn.XLOOKUP($A$2&"-"&I$2, Data_Patch[Outlet ID], Data_Patch[Type], "") | J5: TYPE
A7: NODE2 | B7: PORT1 | C7: PORT2 | D7: PORT3 | E7: PORT4 | F7: PORT5 | G7: PORT6 | H7: PORT7 | I7: PORT8
A8: sACN | B8: =_xlfn.XLOOKUP($A$7&"-"&B$7, Data_Patch[Outlet ID], Data_Patch[Universe], "") -> 0 | C8: =_xlfn.XLOOKUP($A$7&"-"&C$7, Data_Patch[Outlet ID], Data_Patch[Universe], "") -> 0 | D8: =_xlfn.XLOOKUP($A$7&"-"&D$7, Data_Patch[Outlet ID], Data_Patch[Universe], "") -> 0 | E8: =_xlfn.XLOOKUP($A$7&"-"&E$7, Data_Patch[Outlet ID], Data_Patch[Universe], "") -> 0 | F8: =_xlfn.XLOOKUP($A$7&"-"&F$7, Data_Patch[Outlet ID], Data_Patch[Universe], "") -> 0 | G8: =_xlfn.XLOOKUP($A$7&"-"&G$7, Data_Patch[Outlet ID], Data_Patch[Universe], "") -> 0 | H8: =_xlfn.XLOOKUP($A$7&"-"&H$7, Data_Patch[Outlet ID], Data_Patch[Universe], "") -> 0 | I8: =_xlfn.XLOOKUP($A$7&"-"&I$7, Data_Patch[Outlet ID], Data_Patch[Universe], "") -> 0 | J8: UNIVERSE
A9: IP 192.168.0.xxx | B9: =_xlfn.XLOOKUP($A$7&"-"&B$7, Data_Patch[Outlet ID], Data_Patch[Cable], "") | C9: =_xlfn.XLOOKUP($A$7&"-"&C$7, Data_Patch[Outlet ID], Data_Patch[Cable], "") | D9: =_xlfn.XLOOKUP($A$7&"-"&D$7, Data_Patch[Outlet ID], Data_Patch[Cable], "") | E9: =_xlfn.XLOOKUP($A$7&"-"&E$7, Data_Patch[Outlet ID], Data_Patch[Cable], "") | F9: =_xlfn.XLOOKUP($A$7&"-"&F$7, Data_Patch[Outlet ID], Data_Patch[Cable], "") | G9: =_xlfn.XLOOKUP($A$7&"-"&G$7, Data_Patch[Outlet ID], Data_Patch[Cable], "") | H9: =_xlfn.XLOOKUP($A$7&"-"&H$7, Data_Patch[Outlet ID], Data_Patch[Cable], "") | I9: =_xlfn.XLOOKUP($A$7&"-"&I$7, Data_Patch[Outlet ID], Data_Patch[Cable], "") | J9: CABLE
B10: =_xlfn.XLOOKUP($A$7&"-"&B$7, Data_Patch[Outlet ID], Data_Patch[Type], "") | C10: =_xlfn.XLOOKUP($A$7&"-"&C$7, Data_Patch[Outlet ID], Data_Patch[Type], "") | D10: =_xlfn.XLOOKUP($A$7&"-"&D$7, Data_Patch[Outlet ID], Data_Patch[Type], "") | E10: =_xlfn.XLOOKUP($A$7&"-"&E$7, Data_Patch[Outlet ID], Data_Patch[Type], "") | F10: =_xlfn.XLOOKUP($A$7&"-"&F$7, Data_Patch[Outlet ID], Data_Patch[Type], "") | G10: =_xlfn.XLOOKUP($A$7&"-"&G$7, Data_Patch[Outlet ID], Data_Patch[Type], "") | H10: =_xlfn.XLOOKUP($A$7&"-"&H$7, Data_Patch[Outlet ID], Data_Patch[Type], "") | I10: =_xlfn.XLOOKUP($A$7&"-"&I$7, Data_Patch[Outlet ID], Data_Patch[Type], "") | J10: TYPE
B14: 1 | C14: 2 | D14: 3 | E14: 4 | F14: 5 | G14: 6 | H14: 7 | I14: 8
A15: Sneak Panel | B15: =_xlfn.XLOOKUP(B14, Data_Multis[Multi ID], Data_Multis[Multi Name], "") -> DSB1 | C15: =_xlfn.XLOOKUP(C14, Data_Multis[Multi ID], Data_Multis[Multi Name], "") -> SLW1 | D15: =_xlfn.XLOOKUP(D14, Data_Multis[Multi ID], Data_Multis[Multi Name], "") -> THR1 | E15: =_xlfn.XLOOKUP(E14, Data_Multis[Multi ID], Data_Multis[Multi Name], "") -> THR2 | F15: =_xlfn.XLOOKUP(F14, Data_Multis[Multi ID], Data_Multis[Multi Name], "") -> DSL1 | G15: =_xlfn.XLOOKUP(G14, Data_Multis[Multi ID], Data_Multis[Multi Name], "") -> SLWF1 | H15: =_xlfn.XLOOKUP(H14, Data_Multis[Multi ID], Data_Multis[Multi Name], "") -> SRL1 | I15: =_xlfn.XLOOKUP(I14, Data_Multis[Multi ID], Data_Multis[Multi Name], "") -> SLL1
A16: Line1 | B16: =_xlfn.XLOOKUP(B14, Data_Multis[Multi ID], Data_Multis[Line 1], "") -> DSB1 U1 | C16: =_xlfn.XLOOKUP(C14, Data_Multis[Multi ID], Data_Multis[Line 1], "") -> SLW1 U12 | D16: =_xlfn.XLOOKUP(D14, Data_Multis[Multi ID], Data_Multis[Line 1], "") -> THR1 U17 | E16: =_xlfn.XLOOKUP(E14, Data_Multis[Multi ID], Data_Multis[Line 1], "") -> THR5 U21 | F16: =_xlfn.XLOOKUP(F14, Data_Multis[Multi ID], Data_Multis[Line 1], "") -> DSL1 U22 | G16: =_xlfn.XLOOKUP(G14, Data_Multis[Multi ID], Data_Multis[Line 1], "") -> SLWF1 U24 | H16: =_xlfn.XLOOKUP(H14, Data_Multis[Multi ID], Data_Multis[Line 1], "") -> SRL1 U25 | I16: =_xlfn.XLOOKUP(I14, Data_Multis[Multi ID], Data_Multis[Line 1], "") -> SLL1 U29
A17: Line2 | B17: =_xlfn.XLOOKUP(B14, Data_Multis[Multi ID], Data_Multis[Line 2], "") -> DSB2 U2 | C17: =_xlfn.XLOOKUP(C14, Data_Multis[Multi ID], Data_Multis[Line 2], "") -> SLW2 U13 | D17: =_xlfn.XLOOKUP(D14, Data_Multis[Multi ID], Data_Multis[Line 2], "") -> THR2 U18 | E17: =_xlfn.XLOOKUP(E14, Data_Multis[Multi ID], Data_Multis[Line 2], "") | F17: =_xlfn.XLOOKUP(F14, Data_Multis[Multi ID], Data_Multis[Line 2], "") -> DSL2 U23 | G17: =_xlfn.XLOOKUP(G14, Data_Multis[Multi ID], Data_Multis[Line 2], "") | H17: =_xlfn.XLOOKUP(H14, Data_Multis[Multi ID], Data_Multis[Line 2], "") -> SRL2 U26 | I17: =_xlfn.XLOOKUP(I14, Data_Multis[Multi ID], Data_Multis[Line 2], "") -> SLL2 U30
A18: Line3 | B18: =_xlfn.XLOOKUP(B14, Data_Multis[Multi ID], Data_Multis[Line 3], "") | C18: =_xlfn.XLOOKUP(C14, Data_Multis[Multi ID], Data_Multis[Line 3], "") | D18: =_xlfn.XLOOKUP(D14, Data_Multis[Multi ID], Data_Multis[Line 3], "") -> THR3 U19 | E18: =_xlfn.XLOOKUP(E14, Data_Multis[Multi ID], Data_Multis[Line 3], "") | F18: =_xlfn.XLOOKUP(F14, Data_Multis[Multi ID], Data_Multis[Line 3], "") | G18: =_xlfn.XLOOKUP(G14, Data_Multis[Multi ID], Data_Multis[Line 3], "") | H18: =_xlfn.XLOOKUP(H14, Data_Multis[Multi ID], Data_Multis[Line 3], "") -> SRL3 U27 | I18: =_xlfn.XLOOKUP(I14, Data_Multis[Multi ID], Data_Multis[Line 3], "") -> SLL3 U31
A19: Line4 | B19: =_xlfn.XLOOKUP(B14, Data_Multis[Multi ID], Data_Multis[Line 4], "") | C19: =_xlfn.XLOOKUP(C14, Data_Multis[Multi ID], Data_Multis[Line 4], "") | D19: =_xlfn.XLOOKUP(D14, Data_Multis[Multi ID], Data_Multis[Line 4], "") -> THR4 U20 | E19: =_xlfn.XLOOKUP(E14, Data_Multis[Multi ID], Data_Multis[Line 4], "") | F19: =_xlfn.XLOOKUP(F14, Data_Multis[Multi ID], Data_Multis[Line 4], "") | G19: =_xlfn.XLOOKUP(G14, Data_Multis[Multi ID], Data_Multis[Line 4], "") | H19: =_xlfn.XLOOKUP(H14, Data_Multis[Multi ID], Data_Multis[Line 4], "") -> SRL4 U28 | I19: =_xlfn.XLOOKUP(I14, Data_Multis[Multi ID], Data_Multis[Line 4], "") -> SLL4 U32
A21: optiSPLIT | B21: PORT1 | C21: PORT2 | D21: PORT3 | E21: PORT4 | F21: PORT5 | G21: PORT6 | H21: PORT7 | I21: PORT8
J22: CABLE
J23: TYPE
A25: optiSPLIT | B25: PORT1 | C25: PORT2 | D25: PORT3 | E25: PORT4 | F25: PORT5 | G25: PORT6 | H25: PORT7 | I25: PORT8
J26: CABLE
J27: TYPE

Sheet NPU40
A1: NPU 40 | J1: =DATA!$G$2 -> Untitled Show | Q1: #VALUE!
A2: NODE1 | B2: PORT1 | C2: PORT2 | D2: PORT3 | E2: PORT4 | F2: PORT5 | G2: PORT6 | H2: PORT7 | I2: PORT8 | M2: Outlet Count | N2: =COUNTA(Data_Patch[Outlet ID]) -> 144
A3: Universe | B3: =_xlfn.XLOOKUP($A$2&"-"&B$2, Data_Patch[Outlet ID], Data_Patch[Universe], "") -> 1 | C3: =_xlfn.XLOOKUP($A$2&"-"&C$2, Data_Patch[Outlet ID], Data_Patch[Universe], "") -> 2 | D3: =_xlfn.XLOOKUP($A$2&"-"&D$2, Data_Patch[Outlet ID], Data_Patch[Universe], "") -> 0 | E3: =_xlfn.XLOOKUP($A$2&"-"&E$2, Data_Patch[Outlet ID], Data_Patch[Universe], "") -> 0 | F3: =_xlfn.XLOOKUP($A$2&"-"&F$2, Data_Patch[Outlet ID], Data_Patch[Universe], "") -> 12 | G3: =_xlfn.XLOOKUP($A$2&"-"&G$2, Data_Patch[Outlet ID], Data_Patch[Universe], "") -> 13 | H3: =_xlfn.XLOOKUP($A$2&"-"&H$2, Data_Patch[Outlet ID], Data_Patch[Universe], "") -> 0 | I3: =_xlfn.XLOOKUP($A$2&"-"&I$2, Data_Patch[Outlet ID], Data_Patch[Universe], "") -> 0 | J3: UNIVERSE | M3: Outlets | N3: 40
A4: IP 192.168.0.xxx | B4: =_xlfn.XLOOKUP($A$2&"-"&B$2, Data_Patch[Outlet ID], Data_Patch[Cable], "") -> DSB1 | C4: =_xlfn.XLOOKUP($A$2&"-"&C$2, Data_Patch[Outlet ID], Data_Patch[Cable], "") -> DSB2 | D4: =_xlfn.XLOOKUP($A$2&"-"&D$2, Data_Patch[Outlet ID], Data_Patch[Cable], "") | E4: =_xlfn.XLOOKUP($A$2&"-"&E$2, Data_Patch[Outlet ID], Data_Patch[Cable], "") | F4: =_xlfn.XLOOKUP($A$2&"-"&F$2, Data_Patch[Outlet ID], Data_Patch[Cable], "") -> SLW1 | G4: =_xlfn.XLOOKUP($A$2&"-"&G$2, Data_Patch[Outlet ID], Data_Patch[Cable], "") -> SLW2 | H4: =_xlfn.XLOOKUP($A$2&"-"&H$2, Data_Patch[Outlet ID], Data_Patch[Cable], "") | I4: =_xlfn.XLOOKUP($A$2&"-"&I$2, Data_Patch[Outlet ID], Data_Patch[Cable], "") | J4: CABLE
B5: =_xlfn.XLOOKUP($A$2&"-"&B$2, Data_Patch[Outlet ID], Data_Patch[Type], "") -> Sneak | C5: =_xlfn.XLOOKUP($A$2&"-"&C$2, Data_Patch[Outlet ID], Data_Patch[Type], "") -> Sneak | D5: =_xlfn.XLOOKUP($A$2&"-"&D$2, Data_Patch[Outlet ID], Data_Patch[Type], "") | E5: =_xlfn.XLOOKUP($A$2&"-"&E$2, Data_Patch[Outlet ID], Data_Patch[Type], "") | F5: =_xlfn.XLOOKUP($A$2&"-"&F$2, Data_Patch[Outlet ID], Data_Patch[Type], "") -> Sneak | G5: =_xlfn.XLOOKUP($A$2&"-"&G$2, Data_Patch[Outlet ID], Data_Patch[Type], "") -> Sneak | H5: =_xlfn.XLOOKUP($A$2&"-"&H$2, Data_Patch[Outlet ID], Data_Patch[Type], "") | I5: =_xlfn.XLOOKUP($A$2&"-"&I$2, Data_Patch[Outlet ID], Data_Patch[Type], "") | J5: TYPE
A7: NODE2 | B7: PORT1 | C7: PORT2 | D7: PORT3 | E7: PORT4 | F7: PORT5 | G7: PORT6 | H7: PORT7 | I7: PORT8
A8: Universe | B8: =_xlfn.XLOOKUP($A$7&"-"&B$7, Data_Patch[Outlet ID], Data_Patch[Universe], "") -> 0 | C8: =_xlfn.XLOOKUP($A$7&"-"&C$7, Data_Patch[Outlet ID], Data_Patch[Universe], "") -> 0 | D8: =_xlfn.XLOOKUP($A$7&"-"&D$7, Data_Patch[Outlet ID], Data_Patch[Universe], "") -> 0 | E8: =_xlfn.XLOOKUP($A$7&"-"&E$7, Data_Patch[Outlet ID], Data_Patch[Universe], "") -> 0 | F8: =_xlfn.XLOOKUP($A$7&"-"&F$7, Data_Patch[Outlet ID], Data_Patch[Universe], "") -> 0 | G8: =_xlfn.XLOOKUP($A$7&"-"&G$7, Data_Patch[Outlet ID], Data_Patch[Universe], "") -> 0 | H8: =_xlfn.XLOOKUP($A$7&"-"&H$7, Data_Patch[Outlet ID], Data_Patch[Universe], "") -> 0 | I8: =_xlfn.XLOOKUP($A$7&"-"&I$7, Data_Patch[Outlet ID], Data_Patch[Universe], "") -> 0 | J8: UNIVERSE
A9: IP 192.168.0.xxx | B9: =_xlfn.XLOOKUP($A$7&"-"&B$7, Data_Patch[Outlet ID], Data_Patch[Cable], "") | C9: =_xlfn.XLOOKUP($A$7&"-"&C$7, Data_Patch[Outlet ID], Data_Patch[Cable], "") | D9: =_xlfn.XLOOKUP($A$7&"-"&D$7, Data_Patch[Outlet ID], Data_Patch[Cable], "") | E9: =_xlfn.XLOOKUP($A$7&"-"&E$7, Data_Patch[Outlet ID], Data_Patch[Cable], "") | F9: =_xlfn.XLOOKUP($A$7&"-"&F$7, Data_Patch[Outlet ID], Data_Patch[Cable], "") | G9: =_xlfn.XLOOKUP($A$7&"-"&G$7, Data_Patch[Outlet ID], Data_Patch[Cable], "") | H9: =_xlfn.XLOOKUP($A$7&"-"&H$7, Data_Patch[Outlet ID], Data_Patch[Cable], "") | I9: =_xlfn.XLOOKUP($A$7&"-"&I$7, Data_Patch[Outlet ID], Data_Patch[Cable], "") | J9: CABLE
B10: =_xlfn.XLOOKUP($A$7&"-"&B$7, Data_Patch[Outlet ID], Data_Patch[Type], "") | C10: =_xlfn.XLOOKUP($A$7&"-"&C$7, Data_Patch[Outlet ID], Data_Patch[Type], "") | D10: =_xlfn.XLOOKUP($A$7&"-"&D$7, Data_Patch[Outlet ID], Data_Patch[Type], "") | E10: =_xlfn.XLOOKUP($A$7&"-"&E$7, Data_Patch[Outlet ID], Data_Patch[Type], "") | F10: =_xlfn.XLOOKUP($A$7&"-"&F$7, Data_Patch[Outlet ID], Data_Patch[Type], "") | G10: =_xlfn.XLOOKUP($A$7&"-"&G$7, Data_Patch[Outlet ID], Data_Patch[Type], "") | H10: =_xlfn.XLOOKUP($A$7&"-"&H$7, Data_Patch[Outlet ID], Data_Patch[Type], "") | I10: =_xlfn.XLOOKUP($A$7&"-"&I$7, Data_Patch[Outlet ID], Data_Patch[Type], "") | J10: TYPE
A12: NODE3 | B12: PORT1 | C12: PORT2 | D12: PORT3 | E12: PORT4 | F12: PORT5 | G12: PORT6 | H12: PORT7 | I12: PORT8
A13: Universe | B13: =_xlfn.XLOOKUP($A$12&"-"&B$12, Data_Patch[Outlet ID], Data_Patch[Universe], "") -> 0 | C13: =_xlfn.XLOOKUP($A$12&"-"&C$12, Data_Patch[Outlet ID], Data_Patch[Universe], "") -> 0 | D13: =_xlfn.XLOOKUP($A$12&"-"&D$12, Data_Patch[Outlet ID], Data_Patch[Universe], "") -> 0 | E13: =_xlfn.XLOOKUP($A$12&"-"&E$12, Data_Patch[Outlet ID], Data_Patch[Universe], "") -> 0 | F13: =_xlfn.XLOOKUP($A$12&"-"&F$12, Data_Patch[Outlet ID], Data_Patch[Universe], "") -> 0 | G13: =_xlfn.XLOOKUP($A$12&"-"&G$12, Data_Patch[Outlet ID], Data_Patch[Universe], "") -> 0 | H13: =_xlfn.XLOOKUP($A$12&"-"&H$12, Data_Patch[Outlet ID], Data_Patch[Universe], "") -> 0 | I13: =_xlfn.XLOOKUP($A$12&"-"&I$12, Data_Patch[Outlet ID], Data_Patch[Universe], "") -> 0 | J13: UNIVERSE
A14: IP 192.168.0.xxx | B14: =_xlfn.XLOOKUP($A$12&"-"&B$12, Data_Patch[Outlet ID], Data_Patch[Cable], "") | C14: =_xlfn.XLOOKUP($A$12&"-"&C$12, Data_Patch[Outlet ID], Data_Patch[Cable], "") | D14: =_xlfn.XLOOKUP($A$12&"-"&D$12, Data_Patch[Outlet ID], Data_Patch[Cable], "") | E14: =_xlfn.XLOOKUP($A$12&"-"&E$12, Data_Patch[Outlet ID], Data_Patch[Cable], "") | F14: =_xlfn.XLOOKUP($A$12&"-"&F$12, Data_Patch[Outlet ID], Data_Patch[Cable], "") | G14: =_xlfn.XLOOKUP($A$12&"-"&G$12, Data_Patch[Outlet ID], Data_Patch[Cable], "") | H14: =_xlfn.XLOOKUP($A$12&"-"&H$12, Data_Patch[Outlet ID], Data_Patch[Cable], "") | I14: =_xlfn.XLOOKUP($A$12&"-"&I$12, Data_Patch[Outlet ID], Data_Patch[Cable], "") | J14: CABLE
B15: =_xlfn.XLOOKUP($A$12&"-"&B$12, Data_Patch[Outlet ID], Data_Patch[Type], "") | C15: =_xlfn.XLOOKUP($A$12&"-"&C$12, Data_Patch[Outlet ID], Data_Patch[Type], "") | D15: =_xlfn.XLOOKUP($A$12&"-"&D$12, Data_Patch[Outlet ID], Data_Patch[Type], "") | E15: =_xlfn.XLOOKUP($A$12&"-"&E$12, Data_Patch[Outlet ID], Data_Patch[Type], "") | F15: =_xlfn.XLOOKUP($A$12&"-"&F$12, Data_Patch[Outlet ID], Data_Patch[Type], "") | G15: =_xlfn.XLOOKUP($A$12&"-"&G$12, Data_Patch[Outlet ID], Data_Patch[Type], "") | H15: =_xlfn.XLOOKUP($A$12&"-"&H$12, Data_Patch[Outlet ID], Data_Patch[Type], "") | I15: =_xlfn.XLOOKUP($A$12&"-"&I$12, Data_Patch[Outlet ID], Data_Patch[Type], "") | J15: TYPE
A17: NODE4 | B17: PORT1 | C17: PORT2 | D17: PORT3 | E17: PORT4 | F17: PORT5 | G17: PORT6 | H17: PORT7 | I17: PORT8
A18: Universe | B18: =_xlfn.XLOOKUP($A$17&"-"&B$17, Data_Patch[Outlet ID], Data_Patch[Universe], "") -> 0 | C18: =_xlfn.XLOOKUP($A$17&"-"&C$17, Data_Patch[Outlet ID], Data_Patch[Universe], "") -> 0 | D18: =_xlfn.XLOOKUP($A$17&"-"&D$17, Data_Patch[Outlet ID], Data_Patch[Universe], "") -> 0 | E18: =_xlfn.XLOOKUP($A$17&"-"&E$17, Data_Patch[Outlet ID], Data_Patch[Universe], "") -> 0 | F18: =_xlfn.XLOOKUP($A$17&"-"&F$17, Data_Patch[Outlet ID], Data_Patch[Universe], "") -> 0 | G18: =_xlfn.XLOOKUP($A$17&"-"&G$17, Data_Patch[Outlet ID], Data_Patch[Universe], "") -> 0 | H18: =_xlfn.XLOOKUP($A$17&"-"&H$17, Data_Patch[Outlet ID], Data_Patch[Universe], "") -> 0 | I18: =_xlfn.XLOOKUP($A$17&"-"&I$17, Data_Patch[Outlet ID], Data_Patch[Universe], "") -> 0 | J18: UNIVERSE
A19: IP 192.168.0.xxx | B19: =_xlfn.XLOOKUP($A$17&"-"&B$17, Data_Patch[Outlet ID], Data_Patch[Cable], "") | C19: =_xlfn.XLOOKUP($A$17&"-"&C$17, Data_Patch[Outlet ID], Data_Patch[Cable], "") | D19: =_xlfn.XLOOKUP($A$17&"-"&D$17, Data_Patch[Outlet ID], Data_Patch[Cable], "") | E19: =_xlfn.XLOOKUP($A$17&"-"&E$17, Data_Patch[Outlet ID], Data_Patch[Cable], "") | F19: =_xlfn.XLOOKUP($A$17&"-"&F$17, Data_Patch[Outlet ID], Data_Patch[Cable], "") | G19: =_xlfn.XLOOKUP($A$17&"-"&G$17, Data_Patch[Outlet ID], Data_Patch[Cable], "") | H19: =_xlfn.XLOOKUP($A$17&"-"&H$17, Data_Patch[Outlet ID], Data_Patch[Cable], "") | I19: =_xlfn.XLOOKUP($A$17&"-"&I$17, Data_Patch[Outlet ID], Data_Patch[Cable], "") | J19: CABLE
B20: =_xlfn.XLOOKUP($A$17&"-"&B$17, Data_Patch[Outlet ID], Data_Patch[Type], "") | C20: =_xlfn.XLOOKUP($A$17&"-"&C$17, Data_Patch[Outlet ID], Data_Patch[Type], "") | D20: =_xlfn.XLOOKUP($A$17&"-"&D$17, Data_Patch[Outlet ID], Data_Patch[Type], "") | E20: =_xlfn.XLOOKUP($A$17&"-"&E$17, Data_Patch[Outlet ID], Data_Patch[Type], "") | F20: =_xlfn.XLOOKUP($A$17&"-"&F$17, Data_Patch[Outlet ID], Data_Patch[Type], "") | G20: =_xlfn.XLOOKUP($A$17&"-"&G$17, Data_Patch[Outlet ID], Data_Patch[Type], "") | H20: =_xlfn.XLOOKUP($A$17&"-"&H$17, Data_Patch[Outlet ID], Data_Patch[Type], "") | I20: =_xlfn.XLOOKUP($A$17&"-"&I$17, Data_Patch[Outlet ID], Data_Patch[Type], "") | J20: TYPE
A22: NODE5 | B22: PORT1 | C22: PORT2 | D22: PORT3 | E22: PORT4 | F22: PORT5 | G22: PORT6 | H22: PORT7 | I22: PORT8
A23: Universe | B23: =_xlfn.XLOOKUP($A$22&"-"&B$22, Data_Patch[Outlet ID], Data_Patch[Universe], "") -> 0 | C23: =_xlfn.XLOOKUP($A$22&"-"&C$22, Data_Patch[Outlet ID], Data_Patch[Universe], "") -> 0 | D23: =_xlfn.XLOOKUP($A$22&"-"&D$22, Data_Patch[Outlet ID], Data_Patch[Universe], "") -> 0 | E23: =_xlfn.XLOOKUP($A$22&"-"&E$22, Data_Patch[Outlet ID], Data_Patch[Universe], "") -> 0 | F23: =_xlfn.XLOOKUP($A$22&"-"&F$22, Data_Patch[Outlet ID], Data_Patch[Universe], "") -> 0 | G23: =_xlfn.XLOOKUP($A$22&"-"&G$22, Data_Patch[Outlet ID], Data_Patch[Universe], "") -> 0 | H23: =_xlfn.XLOOKUP($A$22&"-"&H$22, Data_Patch[Outlet ID], Data_Patch[Universe], "") -> 0 | I23: =_xlfn.XLOOKUP($A$22&"-"&I$22, Data_Patch[Outlet ID], Data_Patch[Universe], "") -> 0 | J23: UNIVERSE
A24: IP 192.168.0.xxx | B24: =_xlfn.XLOOKUP($A$22&"-"&B$22, Data_Patch[Outlet ID], Data_Patch[Cable], "") | C24: =_xlfn.XLOOKUP($A$22&"-"&C$22, Data_Patch[Outlet ID], Data_Patch[Cable], "") | D24: =_xlfn.XLOOKUP($A$22&"-"&D$22, Data_Patch[Outlet ID], Data_Patch[Cable], "") | E24: =_xlfn.XLOOKUP($A$22&"-"&E$22, Data_Patch[Outlet ID], Data_Patch[Cable], "") | F24: =_xlfn.XLOOKUP($A$22&"-"&F$22, Data_Patch[Outlet ID], Data_Patch[Cable], "") | G24: =_xlfn.XLOOKUP($A$22&"-"&G$22, Data_Patch[Outlet ID], Data_Patch[Cable], "") | H24: =_xlfn.XLOOKUP($A$22&"-"&H$22, Data_Patch[Outlet ID], Data_Patch[Cable], "") | I24: =_xlfn.XLOOKUP($A$22&"-"&I$22, Data_Patch[Outlet ID], Data_Patch[Cable], "") | J24: CABLE
