Workbook
Name ACTIVE_ML: Fixtures!$H$6:$I$40
Name ActiveFixtureNames: Fixtures!$H$7:$H$103
Name ActiveFixtures: Fixtures!$H$7:$I$103
Name ColorLookup_Colors: 'Color Lookup'!$B$2:$B$259
Name ColorLookup_MultiNames: 'Color Lookup'!$A$2:$A$259
Name CON_fixturesamps: Fixtures!$K$6:$L$40
Name cwd: Parameters!$B$2
Name filename: Parameters!$B$3
Name ML_FixturesAmps: Fixtures!$B$6:$C$103

Sheet Fixtures
B2: SHOW: | C2: Untitled Show
B4: Moving Light List | E4: Conventionals List | H4: Active Moving Lights | K4: Active Conventionals
B5: FIXTURES | C5: AMPS | E5: Fixtures | F5: Amps | H5: Fixture | I5: Amps | K5: Fixture | L5: Amps
B7: Acme Pixelline IP | C7: 1.75 | E7: ETC Source 4 Jnr | F7: 2.4 | I7: =IFERROR(VLOOKUP(H7,ML_FixturesAmps,2,FALSE),"") | L7: =IFERROR(VLOOKUP(K7,E7:F103,2,FALSE),"")
B8: Acme Pixelline IP x 2 | C8: 3.5 | E8: ETC Source 4 | F8: 3.5 | I8: =IFERROR(VLOOKUP(H8,ML_FixturesAmps,2,FALSE),"") | L8: =IFERROR(VLOOKUP(K8,E8:F104,2,FALSE),"")
B9: Acme Pixelline IP x 3 | C9: 5.25 | E9: ETC Source 4 PAR | F9: 2.5 | I9: =IFERROR(VLOOKUP(H9,ML_FixturesAmps,2,FALSE),"") | L9: =IFERROR(VLOOKUP(K9,E9:F105,2,FALSE),"")
E10: PAR 56 | F10: 1.25 | I10: =IFERROR(VLOOKUP(H10,ML_FixturesAmps,2,FALSE),"") | L10: =IFERROR(VLOOKUP(K10,E10:F106,2,FALSE),"")
B11: Ayrton Domino | C11: 7.5 | E11: PAR 56 Ray | F11: 2.08 | I11: =IFERROR(VLOOKUP(H11,ML_FixturesAmps,2,FALSE),"") | L11: =IFERROR(VLOOKUP(K11,E11:F107,2,FALSE),"")
B12: Ayrton Perseo | C12: 3.4 | E12: PAR 64 ACL | F12: 1.04 | I12: =IFERROR(VLOOKUP(H12,ML_FixturesAmps,2,FALSE),"") | L12: =IFERROR(VLOOKUP(K12,E12:F108,2,FALSE),"")
B13: Ayrton Perseo x 2 | C13: 6.8 | E13: PAR 64 ACL BO4 | F13: 4.16 | I13: =IFERROR(VLOOKUP(H13,ML_FixturesAmps,2,FALSE),"") | L13: =IFERROR(VLOOKUP(K13,E13:F109,2,FALSE),"")
B14: Ayrton Perseo x 3 | C14: 10.2 | E14: PAR 64 Ray | F14: 2.08 | I14: =IFERROR(VLOOKUP(H14,ML_FixturesAmps,2,FALSE),"") | L14: =IFERROR(VLOOKUP(K14,E14:F110,2,FALSE),"")
E15: PAR 64 Ray BO4 | F15: 8.32 | I15: =IFERROR(VLOOKUP(H15,ML_FixturesAmps,2,FALSE),"") | L15: =IFERROR(VLOOKUP(K15,E15:F111,2,FALSE),"")
B16: CP Mythos | C16: 3 | E16: PAR 64 | F16: 4.16 | I16: =IFERROR(VLOOKUP(H16,ML_FixturesAmps,2,FALSE),"") | L16: =IFERROR(VLOOKUP(K16,E16:F112,2,FALSE),"")
B17: CP Mythos x 2 | C17: 6 | E17: PAR 64 BO4 | F17: 16.5 | I17: =IFERROR(VLOOKUP(H17,ML_FixturesAmps,2,FALSE),"") | L17: =IFERROR(VLOOKUP(K17,E17:F113,2,FALSE),"")
B18: CP Scenious Unico | C18: 6 | E18: PAR 64 BO6 | F18: 25 | I18: =IFERROR(VLOOKUP(H18,ML_FixturesAmps,2,FALSE),"") | L18: =IFERROR(VLOOKUP(K18,E18:F114,2,FALSE),"")
B19: CP Sharpy | C19: 1.5 | E19: Mole - Duet | F19: 5.5 | I19: =IFERROR(VLOOKUP(H19,ML_FixturesAmps,2,FALSE),"") | L19: =IFERROR(VLOOKUP(K19,E19:F115,2,FALSE),"")
B20: CP Sharpy x 2 | C20: 3 | E20: Mole - 4lite | F20: 11 | I20: =IFERROR(VLOOKUP(H20,ML_FixturesAmps,2,FALSE),"") | L20: =IFERROR(VLOOKUP(K20,E20:F116,2,FALSE),"")
B21: CP Sharpy x 3 | C21: 4.5 | E21: Mole - 4lite (A) | F21: 5.5 | I21: =IFERROR(VLOOKUP(H21,ML_FixturesAmps,2,FALSE),"") | L21: =IFERROR(VLOOKUP(K21,E21:F117,2,FALSE),"")
B22: CP Sharpy Wash | C22: 2.2 | E22: Mole - 4lite (B) | F22: 5.5 | I22: =IFERROR(VLOOKUP(H22,ML_FixturesAmps,2,FALSE),"") | L22: =IFERROR(VLOOKUP(K22,E22:F118,2,FALSE),"")
B23: CP Sharpy Wash x 2 | C23: 4.4 | E23: Mole - 8lite (A) | F23: 11 | I23: =IFERROR(VLOOKUP(H23,ML_FixturesAmps,2,FALSE),"") | L23: =IFERROR(VLOOKUP(K23,E23:F119,2,FALSE),"")
B24: CP Sharpy Wash x 2 | C24: 6.6 | E24: Mole - 8lite (B) | F24: 11 | I24: =IFERROR(VLOOKUP(H24,ML_FixturesAmps,2,FALSE),"") | L24: =IFERROR(VLOOKUP(K24,E24:F120,2,FALSE),"")
B25: CP Xtylos | C25: 1.7 | E25: Mole - 8lite (C) | F25: 5.5 | I25: =IFERROR(VLOOKUP(H25,ML_FixturesAmps,2,FALSE),"") | L25: =IFERROR(VLOOKUP(K25,E25:F121,2,FALSE),"")
B26: CP Xtylos x 2 | C26: 3.4 | E26: Mole - 8lite (D) | F26: 5.5 | I26: =IFERROR(VLOOKUP(H26,ML_FixturesAmps,2,FALSE),"") | L26: =IFERROR(VLOOKUP(K26,E26:F122,2,FALSE),"")
B27: CP Xtylos x 3 | C27: 5.1 | E27: 1KW Castor | F27: 4.7 | I27: =IFERROR(VLOOKUP(H27,ML_FixturesAmps,2,FALSE),"") | L27: =IFERROR(VLOOKUP(K27,E27:F123,2,FALSE),"")
E28: 2KW Castor | F28: 8.5 | I28: =IFERROR(VLOOKUP(H28,ML_FixturesAmps,2,FALSE),"") | L28: =IFERROR(VLOOKUP(K28,E28:F124,2,FALSE),"")
B29: Chauvet Strike M | C29: 4 | I29: =IFERROR(VLOOKUP(H29,ML_FixturesAmps,2,FALSE),"") | L29: =IFERROR(VLOOKUP(K29,E29:F125,2,FALSE),"")
B30: Chauvet Strike M x 2 | C30: 8 | I30: =IFERROR(VLOOKUP(H30,ML_FixturesAmps,2,FALSE),"") | L30: =IFERROR(VLOOKUP(K30,E30:F126,2,FALSE),"")
B31: Chauvet Strike M x 3 | C31: 12 | I31: =IFERROR(VLOOKUP(H31,ML_FixturesAmps,2,FALSE),"") | L31: =IFERROR(VLOOKUP(K31,E31:F127,2,FALSE),"")
I32: =IFERROR(VLOOKUP(H32,ML_FixturesAmps,2,FALSE),"") | L32: =IFERROR(VLOOKUP(K32,E32:F128,2,FALSE),"")
B33: EK Blinder II | C33: 1 | I33: =IFERROR(VLOOKUP(H33,ML_FixturesAmps,2,FALSE),"") | L33: =IFERROR(VLOOKUP(K33,E33:F129,2,FALSE),"")
B34: EK Blinder II x 2 | C34: 2 | I34: =IFERROR(VLOOKUP(H34,ML_FixturesAmps,2,FALSE),"") | L34: =IFERROR(VLOOKUP(K34,E34:F130,2,FALSE),"")
B35: EK Blinder II x 4 | C35: 4 | I35: =IFERROR(VLOOKUP(H35,ML_FixturesAmps,2,FALSE),"") | L35: =IFERROR(VLOOKUP(K35,E35:F131,2,FALSE),"")
B36: EK Blinder II x 6 | C36: 6 | I36: =IFERROR(VLOOKUP(H36,ML_FixturesAmps,2,FALSE),"") | L36: =IFERROR(VLOOKUP(K36,E36:F132,2,FALSE),"")
I37: =IFERROR(VLOOKUP(H37,ML_FixturesAmps,2,FALSE),"") | L37: =IFERROR(VLOOKUP(K37,E37:F133,2,FALSE),"")
B38: Elation SixBar | C38: 1 | I38: =IFERROR(VLOOKUP(H38,ML_FixturesAmps,2,FALSE),"") | L38: =IFERROR(VLOOKUP(K38,E38:F134,2,FALSE),"")
B39: Elation SixBar x 2 | C39: 2 | I39: =IFERROR(VLOOKUP(H39,ML_FixturesAmps,2,FALSE),"") | L39: =IFERROR(VLOOKUP(K39,E39:F135,2,FALSE),"")
B40: Elation SixBar x 3 | C40: 3 | I40: =IFERROR(VLOOKUP(H40,ML_FixturesAmps,2,FALSE),"") | L40: =IFERROR(VLOOKUP(K40,E40:F136,2,FALSE),"")
B41: Elation SixBar x 4 | C41: 4 | H41: {=Fixture_Types[]} -> 0 | I41: 0
H42: 0 | I42: 0
B43: GLP JDC 1 | C43: 5.3 | H43: 0 | I43: 0
...

Sheet DMX
C1: DMX Patch
A2: SHOW: | C2: =Fixtures!C2 -> Untitled Show
A4: Uni | B4: Source | C4: Buffer | D4: Location | E4: Type | F4: Patch | G4: Notes

Sheet SNEAK
A1: Sneak Snake Assignments
A2: SHOW: | C2: =Fixtures!C2 -> Untitled Show
A4: Location | B4: Line# | E4: Location | F4: Line#
B5: 1 | F5: 1
B6: 2 | F6: 2
B7: 3 | F7: 3
B8: 4 | F8: 4
A10: Location | B10: Line# | E10: Location | F10: Line#
B11: 1 | F11: 1
B12: 2 | F12: 2
B13: 3 | F13: 3
B14: 4 | F14: 4
A16: Location | B16: Line# | E16: Location | F16: Line#
B17: 1 | F17: 1
B18: 2 | F18: 2
B19: 3 | F19: 3
B20: 4 | F20: 4
A22: Location | B22: Line# | E22: Location | F22: Line#
B23: 1 | F23: 1
B24: 2 | F24: 2
B25: 3 | F25: 3
B26: 4 | F26: 4
A28: Location | B28: Line# | E28: Location | F28: Line#
B29: 1 | F29: 1
B30: 2 | F30: 2
B31: 3 | F31: 3
B32: 4 | F32: 4
A34: Location | B34: Line# | E34: Location | F34: Line#
B35: 1 | F35: 1
B36: 2 | F36: 2
B37: 3 | F37: 3
B38: 4 | F38: 4
A40: Location | B40: Line# | E40: Location | F40: Line#
B41: 1 | F41: 1
B42: 2 | F42: 2
B43: 3 | F43: 3
B44: 4 | F44: 4
A46: Location | B46: Line# | E46: Location | F46: Line#
B47: 1 | F47: 1
B48: 2 | F48: 2
...

Sheet Parameters
A1: name | B1: value | C1: comment
A2: cwd | B2: {=LEFT(CELL("filename"),FIND("[",CELL("filename"),1)-1)} -> C:\Users\charl\Documents\Code Projects\sidekick\assets\excel\ | C2: Unf*ckingbelievable that you have to do this just to get a relative path
A3: filename | B3: phase_reference_data.xlsx
A4: template_file_version | B4: 4 | C4: Tracks if template files are being correctly updated in the assetBundle.
A16: Template Changelog
A17: Version | B17: Changes
A18: 3 | B18: Adjusted Conditional Formatting Ranges to improve performance
A19: 4 | B19: Implemented Custom Rack assignment

Sheet Fixture Types
A1: Fixture | B1: Amps

Sheet Color Lookup
A1: Multicore Name | B1: Color
A2: DSB1 | B2: red
A3: DSB2 | B3: red
A4: DSB3 | B4: red
A5: DSB4 | B5: red
A6: DSS1 | B6: red
A7: DSS2 | B7: red
A8: MDS1 | B8: white
A9: MDS2 | B9: white
A10: MUS1 | B10: white
A11: MUS2 | B11: white
A12: US1 | B12: blue
... A84: A3.3 | B84: grey

Sheet Power Patch
A1: Rack Name | B1: Rack Type | C1: Rack Number | D1: Rack Outlet Number | E1: Combined Rack Number and Outlet | F1: Multi Name | G1: Patch Outlet | H1: Fixture Type | I1: Fixture Number | J1: Location

Sheet Rack 1
B2: SHOW | D2: =Fixtures!C2 -> Untitled Show
B3: RACK# | D3: 1
B4: NAME / TYPE | D4: =_xlfn.IFNA(_xlfn.XLOOKUP($D$3, Power_Patch[Rack Number],Power_Patch[Rack Name]), "") | F4: =_xlfn.IFNA(_xlfn.XLOOKUP($D$3, Power_Patch[Rack Number],Power_Patch[Rack Type]), "")
C5: CHL | D5: CIRCUT | E5: FIXTURE | F5: FIX. NO. | G5: LOCATION | H5: AMPS | K5: Lookup Value
B6: Loom ID | C6: 1 | D6: =B7&".1" -> .1 | E6: =_xlfn.IFNA(_xlfn.XLOOKUP($K6, Power_Patch[Combined Rack Number and Outlet],Power_Patch[Fixture Type]), "") | F6: =_xlfn.IFNA(_xlfn.XLOOKUP($K6, Power_Patch[Combined Rack Number and Outlet],Power_Patch[Fixture Number]), "") | G6: =_xlfn.IFNA(_xlfn.XLOOKUP($K6, Power_Patch[Combined Rack Number and Outlet],Power_Patch[Location]), "") | H6: =IFERROR(VLOOKUP(E6,ActiveFixtures,2,FALSE),"") | K6: =IF(ISBLANK(C6), "", $D$3&"-"&$C6) -> 1-1
B7: =_xlfn.IFNA(_xlfn.XLOOKUP($K6, Power_Patch[Combined Rack Number and Outlet],Power_Patch[Multi Name]), "") | C7: 2 | D7: =B7&".2" -> .2 | E7: =_xlfn.IFNA(_xlfn.XLOOKUP($K7, Power_Patch[Combined Rack Number and Outlet],Power_Patch[Fixture Type]), "") | F7: =_xlfn.IFNA(_xlfn.XLOOKUP($K7, Power_Patch[Combined Rack Number and Outlet],Power_Patch[Fixture Number]), "") | H7: =IFERROR(VLOOKUP(E7,ActiveFixtures,2,FALSE),"") | K7: =IF(ISBLANK(C7), "", $D$3&"-"&$C7) -> 1-2
C8: 3 | D8: =B7&".3" -> .3 | E8: =_xlfn.IFNA(_xlfn.XLOOKUP($K8, Power_Patch[Combined Rack Number and Outlet],Power_Patch[Fixture Type]), "") | F8: =_xlfn.IFNA(_xlfn.XLOOKUP($K8, Power_Patch[Combined Rack Number and Outlet],Power_Patch[Fixture Number]), "") | H8: =IFERROR(VLOOKUP(E8,ActiveFixtures,2,FALSE),"") | K8: =IF(ISBLANK(C8), "", $D$3&"-"&$C8) -> 1-3
C9: 4 | D9: =B7&".4" -> .4 | E9: =_xlfn.IFNA(_xlfn.XLOOKUP($K9, Power_Patch[Combined Rack Number and Outlet],Power_Patch[Fixture Type]), "") | F9: =_xlfn.IFNA(_xlfn.XLOOKUP($K9, Power_Patch[Combined Rack Number and Outlet],Power_Patch[Fixture Number]), "") | H9: =IFERROR(VLOOKUP(E9,ActiveFixtures,2,FALSE),"") | K9: =IF(ISBLANK(C9), "", $D$3&"-"&$C9) -> 1-4
C10: 5 | D10: =B7&".5" -> .5 | E10: =_xlfn.IFNA(_xlfn.XLOOKUP($K10, Power_Patch[Combined Rack Number and Outlet],Power_Patch[Fixture Type]), "") | F10: =_xlfn.IFNA(_xlfn.XLOOKUP($K10, Power_Patch[Combined Rack Number and Outlet],Power_Patch[Fixture Number]), "") | H10: =IFERROR(VLOOKUP(E10,ActiveFixtures,2,FALSE),"") | K10: =IF(ISBLANK(C10), "", $D$3&"-"&$C10) -> 1-5
C11: 6 | D11: =B7&".6" -> .6 | E11: =_xlfn.IFNA(_xlfn.XLOOKUP($K11, Power_Patch[Combined Rack Number and Outlet],Power_Patch[Fixture Type]), "") | F11: =_xlfn.IFNA(_xlfn.XLOOKUP($K11, Power_Patch[Combined Rack Number and Outlet],Power_Patch[Fixture Number]), "") | H11: =IFERROR(VLOOKUP(E11,ActiveFixtures,2,FALSE),"") | K11: =IF(ISBLANK(C11), "", $D$3&"-"&$C11) -> 1-6
K12: =IF(ISBLANK(C12), "", $D$3&"-"&$C12)
B13: Loom ID | C13: 7 | D13: =B14&".1" -> .1 | E13: =_xlfn.IFNA(_xlfn.XLOOKUP($K13, Power_Patch[Combined Rack Number and Outlet],Power_Patch[Fixture Type]), "") | F13: =_xlfn.IFNA(_xlfn.XLOOKUP($K13, Power_Patch[Combined Rack Number and Outlet],Power_Patch[Fixture Number]), "") | G13: =_xlfn.IFNA(_xlfn.XLOOKUP($K13, Power_Patch[Combined Rack Number and Outlet],Power_Patch[Location]), "") | H13: =IFERROR(VLOOKUP(E13,ActiveFixtures,2,FALSE),"") | K13: =IF(ISBLANK(C13), "", $D$3&"-"&$C13) -> 1-7
B14: =_xlfn.IFNA(_xlfn.XLOOKUP($K13, Power_Patch[Combined Rack Number and Outlet],Power_Patch[Multi Name]), "") | C14: 8 | D14: =B14&".2" -> .2 | E14: =_xlfn.IFNA(_xlfn.XLOOKUP($K14, Power_Patch[Combined Rack Number and Outlet],Power_Patch[Fixture Type]), "") | F14: =_xlfn.IFNA(_xlfn.XLOOKUP($K14, Power_Patch[Combined Rack Number and Outlet],Power_Patch[Fixture Number]), "") | H14: =IFERROR(VLOOKUP(E14,ActiveFixtures,2,FALSE),"") | K14: =IF(ISBLANK(C14), "", $D$3&"-"&$C14) -> 1-8
C15: 9 | D15: =B14&".3" -> .3 | E15: =_xlfn.IFNA(_xlfn.XLOOKUP($K15, Power_Patch[Combined Rack Number and Outlet],Power_Patch[Fixture Type]), "") | F15: =_xlfn.IFNA(_xlfn.XLOOKUP($K15, Power_Patch[Combined Rack Number and Outlet],Power_Patch[Fixture Number]), "") | H15: =IFERROR(VLOOKUP(E15,ActiveFixtures,2,FALSE),"") | K15: =IF(ISBLANK(C15), "", $D$3&"-"&$C15) -> 1-9
C16: 10 | D16: =B14&".4" -> .4 | E16: =_xlfn.IFNA(_xlfn.XLOOKUP($K16, Power_Patch[Combined Rack Number and Outlet],Power_Patch[Fixture Type]), "") | F16: =_xlfn.IFNA(_xlfn.XLOOKUP($K16, Power_Patch[Combined Rack Number and Outlet],Power_Patch[Fixture Number]), "") | H16: =IFERROR(VLOOKUP(E16,ActiveFixtures,2,FALSE),"") | K16: =IF(ISBLANK(C16), "", $D$3&"-"&$C16) -> 1-10
C17: 11 | D17: =B14&".5" -> .5 | E17: =_xlfn.IFNA(_xlfn.XLOOKUP($K17, Power_Patch[Combined Rack Number and Outlet],Power_Patch[Fixture Type]), "") | F17: =_xlfn.IFNA(_xlfn.XLOOKUP($K17, Power_Patch[Combined Rack Number and Outlet],Power_Patch[Fixture Number]), "") | H17: =IFERROR(VLOOKUP(E17,ActiveFixtures,2,FALSE),"") | K17: =IF(ISBLANK(C17), "", $D$3&"-"&$C17) -> 1-11
C18: 12 | D18: =B14&".6" -> .6 | E18: =_xlfn.IFNA(_xlfn.XLOOKUP($K18, Power_Patch[Combined Rack Number and Outlet],Power_Patch[Fixture Type]), "") | F18: =_xlfn.IFNA(_xlfn.XLOOKUP($K18, Power_Patch[Combined Rack Number and Outlet],Power_Patch[Fixture Number]), "") | H18: =IFERROR(VLOOKUP(E18,ActiveFixtures,2,FALSE),"") | K18: =IF(ISBLANK(C18), "", $D$3&"-"&$C18) -> 1-12
K19: =IF(ISBLANK(C19), "", $D$3&"-"&$C19)
B20: Loom ID | C20: 13 | D20: =B21&".1" -> .1 | E20: =_xlfn.IFNA(_xlfn.XLOOKUP($K20, Power_Patch[Combined Rack Number and Outlet],Power_Patch[Fixture Type]), "") | F20: =_xlfn.IFNA(_xlfn.XLOOKUP($K20, Power_Patch[Combined Rack Number and Outlet],Power_Patch[Fixture Number]), "") | G20: =_xlfn.IFNA(_xlfn.XLOOKUP($K20, Power_Patch[Combined Rack Number and Outlet],Power_Patch[Location]), "") | H20: =IFERROR(VLOOKUP(E20,ActiveFixtures,2,FALSE),"") | K20: =IF(ISBLANK(C20), "", $D$3&"-"&$C20) -> 1-13
B21: =_xlfn.IFNA(_xlfn.XLOOKUP($K20, Power_Patch[Combined Rack Number and Outlet],Power_Patch[Multi Name]), "") | C21: 14 | D21: =B21&".2" -> .2 | E21: =_xlfn.IFNA(_xlfn.XLOOKUP($K21, Power_Patch[Combined Rack Number and Outlet],Power_Patch[Fixture Type]), "") | F21: =_xlfn.IFNA(_xlfn.XLOOKUP($K21, Power_Patch[Combined Rack Number and Outlet],Power_Patch[Fixture Number]), "") | H21: =IFERROR(VLOOKUP(E21,ActiveFixtures,2,FALSE),"") | K21: =IF(ISBLANK(C21), "", $D$3&"-"&$C21) -> 1-14
C22: 15 | D22: =B21&".3" -> .3 | E22: =_xlfn.IFNA(_xlfn.XLOOKUP($K22, Power_Patch[Combined Rack Number and Outlet],Power_Patch[Fixture Type]), "") | F22: =_xlfn.IFNA(_xlfn.XLOOKUP($K22, Power_Patch[Combined Rack Number and Outlet],Power_Patch[Fixture Number]), "") | H22: =IFERROR(VLOOKUP(E22,ActiveFixtures,2,FALSE),"") | K22: =IF(ISBLANK(C22), "", $D$3&"-"&$C22) -> 1-15
C23: 16 | D23: =B21&".4" -> .4 | E23: =_xlfn.IFNA(_xlfn.XLOOKUP($K23, Power_Patch[Combined Rack Number and Outlet],Power_Patch[Fixture Type]), "") | F23: =_xlfn.IFNA(_xlfn.XLOOKUP($K23, Power_Patch[Combined Rack Number and Outlet],Power_Patch[Fixture Number]), "") | H23: =IFERROR(VLOOKUP(E23,ActiveFixtures,2,FALSE),"") | K23: =IF(ISBLANK(C23), "", $D$3&"-"&$C23) -> 1-16
C24: 17 | D24: =B21&".5" -> .5 | E24: =_xlfn.IFNA(_xlfn.XLOOKUP($K24, Power_Patch[Combined Rack Number and Outlet],Power_Patch[Fixture Type]), "") | F24: =_xlfn.IFNA(_xlfn.XLOOKUP($K24, Power_Patch[Combined Rack Number and Outlet],Power_Patch[Fixture Number]), "") | H24: =IFERROR(VLOOKUP(E24,ActiveFixtures,2,FALSE),"") | K24: =IF(ISBLANK(C24), "", $D$3&"-"&$C24) -> 1-17
C25: 18 | D25: =B21&".6" -> .6 | E25: =_xlfn.IFNA(_xlfn.XLOOKUP($K25, Power_Patch[Combined Rack Number and Outlet],Power_Patch[Fixture Type]), "") | F25: =_xlfn.IFNA(_xlfn.XLOOKUP($K25, Power_Patch[Combined Rack Number and Outlet],Power_Patch[Fixture Number]), "") | H25: =IFERROR(VLOOKUP(E25,ActiveFixtures,2,FALSE),"") | K25: =IF(ISBLANK(C25), "", $D$3&"-"&$C25) -> 1-18
K26: =IF(ISBLANK(C26), "", $D$3&"-"&$C26)
B27: Loom ID | C27: 19 | D27: =B28&".1" -> .1 | E27: =_xlfn.IFNA(_xlfn.XLOOKUP($K27, Power_Patch[Combined Rack Number and Outlet],Power_Patch[Fixture Type]), "") | F27: =_xlfn.IFNA(_xlfn.XLOOKUP($K27, Power_Patch[Combined Rack Number and Outlet],Power_Patch[Fixture Number]), "") | G27: =_xlfn.IFNA(_xlfn.XLOOKUP($K27, Power_Patch[Combined Rack Number and Outlet],Power_Patch[Location]), "") | H27: =IFERROR(VLOOKUP(E27,ActiveFixtures,2,FALSE),"") | K27: =IF(ISBLANK(C27), "", $D$3&"-"&$C27) -> 1-19
B28: =_xlfn.IFNA(_xlfn.XLOOKUP($K27, Power_Patch[Combined Rack Number and Outlet],Power_Patch[Multi Name]), "") | C28: 20 | D28: =B28&".2" -> .2 | E28: =_xlfn.IFNA(_xlfn.XLOOKUP($K28, Power_Patch[Combined Rack Number and Outlet],Power_Patch[Fixture Type]), "") | F28: =_xlfn.IFNA(_xlfn.XLOOKUP($K28, Power_Patch[Combined Rack Number and Outlet],Power_Patch[Fixture Number]), "") | H28: =IFERROR(VLOOKUP(E28,ActiveFixtures,2,FALSE),"") | K28: =IF(ISBLANK(C28), "", $D$3&"-"&$C28) -> 1-20
C29: 21 | D29: =B28&".3" -> .3 | E29: =_xlfn.IFNA(_xlfn.XLOOKUP($K29, Power_Patch[Combined Rack Number and Outlet],Power_Patch[Fixture Type]), "") | F29: =_xlfn.IFNA(_xlfn.XLOOKUP($K29, Power_Patch[Combined Rack Number and Outlet],Power_Patch[Fixture Number]), "") | H29: =IFERROR(VLOOKUP(E29,ActiveFixtures,2,FALSE),"") | K29: =IF(ISBLANK(C29), "", $D$3&"-"&$C29) -> 1-21
C30: 22 | D30: =B28&".4" -> .4 | E30: =_xlfn.IFNA(_xlfn.XLOOKUP($K30, Power_Patch[Combined Rack Number and Outlet],Power_Patch[Fixture Type]), "") | F30: =_xlfn.IFNA(_xlfn.XLOOKUP($K30, Power_Patch[Combined Rack Number and Outlet],Power_Patch[Fixture Number]), "") | H30: =IFERROR(VLOOKUP(E30,ActiveFixtures,2,FALSE),"") | K30: =IF(ISBLANK(C30), "", $D$3&"-"&$C30) -> 1-22
C31: 23 | D31: =B28&".5" -> .5 | E31: =_xlfn.IFNA(_xlfn.XLOOKUP($K31, Power_Patch[Combined Rack Number and Outlet],Power_Patch[Fixture Type]), "") | F31: =_xlfn.IFNA(_xlfn.XLOOKUP($K31, Power_Patch[Combined Rack Number and Outlet],Power_Patch[Fixture Number]), "") | H31: =IFERROR(VLOOKUP(E31,ActiveFixtures,2,FALSE),"") | K31: =IF(ISBLANK(C31), "", $D$3&"-"&$C31) -> 1-23
C32: 24 | D32: =B28&".6" -> .6 | E32: =_xlfn.IFNA(_xlfn.XLOOKUP($K32, Power_Patch[Combined Rack Number and Outlet],Power_Patch[Fixture Type]), "") | F32: =_xlfn.IFNA(_xlfn.XLOOKUP($K32, Power_Patch[Combined Rack Number and Outlet],Power_Patch[Fixture Number]), "") | H32: =IFERROR(VLOOKUP(E32,ActiveFixtures,2,FALSE),"") | K32: =IF(ISBLANK(C32), "", $D$3&"-"&$C32) -> 1-24
K33: =IF(ISBLANK(C33), "", $D$3&"-"&$C33)
B34: Loom ID | C34: 25 | D34: =B35&".1" -> .1 | E34: =_xlfn.IFNA(_xlfn.XLOOKUP($K34, Power_Patch[Combined Rack Number and Outlet],Power_Patch[Fixture Type]), "") | F34: =_xlfn.IFNA(_xlfn.XLOOKUP($K34, Power_Patch[Combined Rack Number and Outlet],Power_Patch[Fixture Number]), "") | G34: =_xlfn.IFNA(_xlfn.XLOOKUP($K34, Power_Patch[Combined Rack Number and Outlet],Power_Patch[Location]), "") | H34: =IFERROR(VLOOKUP(E34,ActiveFixtures,2,FALSE),"") | K34: =IF(ISBLANK(C34), "", $D$3&"-"&$C34) -> 1-25
B35: =_xlfn.IFNA(_xlfn.XLOOKUP($K34, Power_Patch[Combined Rack Number and Outlet],Power_Patch[Multi Name]), "") | C35: 26 | D35: =B35&".2" -> .2 | E35: =_xlfn.IFNA(_xlfn.XLOOKUP($K35, Power_Patch[Combined Rack Number and Outlet],Power_Patch[Fixture Type]), "") | F35: =_xlfn.IFNA(_xlfn.XLOOKUP($K35, Power_Patch[Combined Rack Number and Outlet],Power_Patch[Fixture Number]), "") | H35: =IFERROR(VLOOKUP(E35,ActiveFixtures,2,FALSE),"") | K35: =IF(ISBLANK(C35), "", $D$3&"-"&$C35) -> 1-26
C36: 27 | D36: =B35&".3" -> .3 | E36: =_xlfn.IFNA(_xlfn.XLOOKUP($K36, Power_Patch[Combined Rack Number and Outlet],Power_Patch[Fixture Type]), "") | F36: =_xlfn.IFNA(_xlfn.XLOOKUP($K36, Power_Patch[Combined Rack Number and Outlet],Power_Patch[Fixture Number]), "") | H36: =IFERROR(VLOOKUP(E36,ActiveFixtures,2,FALSE),"") | K36: =IF(ISBLANK(C36), "", $D$3&"-"&$C36) -> 1-27
C37: 28 | D37: =B35&".4" -> .4 | E37: =_xlfn.IFNA(_xlfn.XLOOKUP($K37, Power_Patch[Combined Rack Number and Outlet],Power_Patch[Fixture Type]), "") | F37: =_xlfn.IFNA(_xlfn.XLOOKUP($K37, Power_Patch[Combined Rack Number and Outlet],Power_Patch[Fixture Number]), "") | H37: =IFERROR(VLOOKUP(E37,ActiveFixtures,2,FALSE),"") | K37: =IF(ISBLANK(C37), "", $D$3&"-"&$C37) -> 1-28
C38: 29 | D38: =B35&".5" -> .5 | E38: =_xlfn.IFNA(_xlfn.XLOOKUP($K38, Power_Patch[Combined Rack Number and Outlet],Power_Patch[Fixture Type]), "") | F38: =_xlfn.IFNA(_xlfn.XLOOKUP($K38, Power_Patch[Combined Rack Number and Outlet],Power_Patch[Fixture Number]), "") | H38: =IFERROR(VLOOKUP(E38,ActiveFixtures,2,FALSE),"") | K38: =IF(ISBLANK(C38), "", $D$3&"-"&$C38) -> 1-29
C39: 30 | D39: =B35&".6" -> .6 | E39: =_xlfn.IFNA(_xlfn.XLOOKUP($K39, Power_Patch[Combined Rack Number and Outlet],Power_Patch[Fixture Type]), "") | F39: =_xlfn.IFNA(_xlfn.XLOOKUP($K39, Power_Patch[Combined Rack Number and Outlet],Power_Patch[Fixture Number]), "") | H39: =IFERROR(VLOOKUP(E39,ActiveFixtures,2,FALSE),"") | K39: =IF(ISBLANK(C39), "", $D$3&"-"&$C39) -> 1-30
K40: =IF(ISBLANK(C40), "", $D$3&"-"&$C40)
B41: Loom ID | C41: 31 | D41: =B42&".1" -> .1 | E41: =_xlfn.IFNA(_xlfn.XLOOKUP($K41, Power_Patch[Combined Rack Number and Outlet],Power_Patch[Fixture Type]), "") | F41: =_xlfn.IFNA(_xlfn.XLOOKUP($K41, Power_Patch[Combined Rack Number and Outlet],Power_Patch[Fixture Number]), "") | G41: =_xlfn.IFNA(_xlfn.XLOOKUP($K41, Power_Patch[Combined Rack Number and Outlet],Power_Patch[Location]), "") | H41: =IFERROR(VLOOKUP(E41,ActiveFixtures,2,FALSE),"") | K41: =IF(ISBLANK(C41), "", $D$3&"-"&$C41) -> 1-31
...

Sheet Rack 2
B2: SHOW | D2: =Fixtures!C2 -> Untitled Show
B3: RACK# | D3: 2
B4: NAME / TYPE | D4: =_xlfn.IFNA(_xlfn.XLOOKUP($D$3, Power_Patch[Rack Number],Power_Patch[Rack Name]), "") | F4: =_xlfn.IFNA(_xlfn.XLOOKUP($D$3, Power_Patch[Rack Number],Power_Patch[Rack Type]), "")
C5: CHL | D5: CIRCUT | E5: FIXTURE | F5: FIX. NO. | G5: LOCATION | H5: AMPS | K5: Lookup Value
B6: Loom ID | C6: 1 | D6: =B7&".1" -> .1 | E6: =_xlfn.IFNA(_xlfn.XLOOKUP($K6, Power_Patch[Combined Rack Number and Outlet],Power_Patch[Fixture Type]), "") | F6: =_xlfn.IFNA(_xlfn.XLOOKUP($K6, Power_Patch[Combined Rack Number and Outlet],Power_Patch[Fixture Number]), "") | G6: =_xlfn.IFNA(_xlfn.XLOOKUP($K6, Power_Patch[Combined Rack Number and Outlet],Power_Patch[Location]), "") | H6: =IFERROR(VLOOKUP(E6,ActiveFixtures,2,FALSE),"") | K6: =IF(ISBLANK(C6), "", $D$3&"-"&$C6) -> 2-1
B7: =_xlfn.IFNA(_xlfn.XLOOKUP($K6, Power_Patch[Combined Rack Number and Outlet],Power_Patch[Multi Name]), "") | C7: 2 | D7: =B7&".2" -> .2 | E7: =_xlfn.IFNA(_xlfn.XLOOKUP($K7, Power_Patch[Combined Rack Number and Outlet],Power_Patch[Fixture Type]), "") | F7: =_xlfn.IFNA(_xlfn.XLOOKUP($K7, Power_Patch[Combined Rack Number and Outlet],Power_Patch[Fixture Number]), "") | H7: =IFERROR(VLOOKUP(E7,ActiveFixtures,2,FALSE),"") | K7: =IF(ISBLANK(C7), "", $D$3&"-"&$C7) -> 2-2
C8: 3 | D8: =B7&".3" -> .3 | E8: =_xlfn.IFNA(_xlfn.XLOOKUP($K8, Power_Patch[Combined Rack Number and Outlet],Power_Patch[Fixture Type]), "") | F8: =_xlfn.IFNA(_xlfn.XLOOKUP($K8, Power_Patch[Combined Rack Number and Outlet],Power_Patch[Fixture Number]), "") | H8: =IFERROR(VLOOKUP(E8,ActiveFixtures,2,FALSE),"") | K8: =IF(ISBLANK(C8), "", $D$3&"-"&$C8) -> 2-3
C9: 4 | D9: =B7&".4" -> .4 | E9: =_xlfn.IFNA(_xlfn.XLOOKUP($K9, Power_Patch[Combined Rack Number and Outlet],Power_Patch[Fixture Type]), "") | F9: =_xlfn.IFNA(_xlfn.XLOOKUP($K9, Power_Patch[Combined Rack Number and Outlet],Power_Patch[Fixture Number]), "") | H9: =IFERROR(VLOOKUP(E9,ActiveFixtures,2,FALSE),"") | K9: =IF(ISBLANK(C9), "", $D$3&"-"&$C9) -> 2-4
C10: 5 | D10: =B7&".5" -> .5 | E10: =_xlfn.IFNA(_xlfn.XLOOKUP($K10, Power_Patch[Combined Rack Number and Outlet],Power_Patch[Fixture Type]), "") | F10: =_xlfn.IFNA(_xlfn.XLOOKUP($K10, Power_Patch[Combined Rack Number and Outlet],Power_Patch[Fixture Number]), "") | H10: =IFERROR(VLOOKUP(E10,ActiveFixtures,2,FALSE),"") | K10: =IF(ISBLANK(C10), "", $D$3&"-"&$C10) -> 2-5
C11: 6 | D11: =B7&".6" -> .6 | E11: =_xlfn.IFNA(_xlfn.XLOOKUP($K11, Power_Patch[Combined Rack Number and Outlet],Power_Patch[Fixture Type]), "") | F11: =_xlfn.IFNA(_xlfn.XLOOKUP($K11, Power_Patch[Combined Rack Number and Outlet],Power_Patch[Fixture Number]), "") | H11: =IFERROR(VLOOKUP(E11,ActiveFixtures,2,FALSE),"") | K11: =IF(ISBLANK(C11), "", $D$3&"-"&$C11) -> 2-6
K12: =IF(ISBLANK(C12), "", $D$3&"-"&$C12)
B13: Loom ID | C13: 7 | D13: =B14&".1" -> .1 | E13: =_xlfn.IFNA(_xlfn.XLOOKUP($K13, Power_Patch[Combined Rack Number and Outlet],Power_Patch[Fixture Type]), "") | F13: =_xlfn.IFNA(_xlfn.XLOOKUP($K13, Power_Patch[Combined Rack Number and Outlet],Power_Patch[Fixture Number]), "") | G13: =_xlfn.IFNA(_xlfn.XLOOKUP($K13, Power_Patch[Combined Rack Number and Outlet],Power_Patch[Location]), "") | H13: =IFERROR(VLOOKUP(E13,ActiveFixtures,2,FALSE),"") | K13: =IF(ISBLANK(C13), "", $D$3&"-"&$C13) -> 2-7
B14: =_xlfn.IFNA(_xlfn.XLOOKUP($K13, Power_Patch[Combined Rack Number and Outlet],Power_Patch[Multi Name]), "") | C14: 8 | D14: =B14&".2" -> .2 | E14: =_xlfn.IFNA(_xlfn.XLOOKUP($K14, Power_Patch[Combined Rack Number and Outlet],Power_Patch[Fixture Type]), "") | F14: =_xlfn.IFNA(_xlfn.XLOOKUP($K14, Power_Patch[Combined Rack Number and Outlet],Power_Patch[Fixture Number]), "") | H14: =IFERROR(VLOOKUP(E14,ActiveFixtures,2,FALSE),"") | K14: =IF(ISBLANK(C14), "", $D$3&"-"&$C14) -> 2-8
C15: 9 | D15: =B14&".3" -> .3 | E15: =_xlfn.IFNA(_xlfn.XLOOKUP($K15, Power_Patch[Combined Rack Number and Outlet],Power_Patch[Fixture Type]), "") | F15: =_xlfn.IFNA(_xlfn.XLOOKUP($K15, Power_Patch[Combined Rack Number and Outlet],Power_Patch[Fixture Number]), "") | H15: =IFERROR(VLOOKUP(E15,ActiveFixtures,2,FALSE),"") | K15: =IF(ISBLANK(C15), "", $D$3&"-"&$C15) -> 2-9
C16: 10 | D16: =B14&".4" -> .4 | E16: =_xlfn.IFNA(_xlfn.XLOOKUP($K16, Power_Patch[Combined Rack Number and Outlet],Power_Patch[Fixture Type]), "") | F16: =_xlfn.IFNA(_xlfn.XLOOKUP($K16, Power_Patch[Combined Rack Number and Outlet],Power_Patch[Fixture Number]), "") | H16: =IFERROR(VLOOKUP(E16,ActiveFixtures,2,FALSE),"") | K16: =IF(ISBLANK(C16), "", $D$3&"-"&$C16) -> 2-10
C17: 11 | D17: =B14&".5" -> .5 | E17: =_xlfn.IFNA(_xlfn.XLOOKUP($K17, Power_Patch[Combined Rack Number and Outlet],Power_Patch[Fixture Type]), "") | F17: =_xlfn.IFNA(_xlfn.XLOOKUP($K17, Power_Patch[Combined Rack Number and Outlet],Power_Patch[Fixture Number]), "") | H17: =IFERROR(VLOOKUP(E17,ActiveFixtures,2,FALSE),"") | K17: =IF(ISBLANK(C17), "", $D$3&"-"&$C17) -> 2-11
C18: 12 | D18: =B14&".6" -> .6 | E18: =_xlfn.IFNA(_xlfn.XLOOKUP($K18, Power_Patch[Combined Rack Number and Outlet],Power_Patch[Fixture Type]), "") | F18: =_xlfn.IFNA(_xlfn.XLOOKUP($K18, Power_Patch[Combined Rack Number and Outlet],Power_Patch[Fixture Number]), "") | H18: =IFERROR(VLOOKUP(E18,ActiveFixtures,2,FALSE),"") | K18: =IF(ISBLANK(C18), "", $D$3&"-"&$C18) -> 2-12
K19: =IF(ISBLANK(C19), "", $D$3&"-"&$C19)
B20: Loom ID | C20: 13 | D20: =B21&".1" -> .1 | E20: =_xlfn.IFNA(_xlfn.XLOOKUP($K20, Power_Patch[Combined Rack Number and Outlet],Power_Patch[Fixture Type]), "") | F20: =_xlfn.IFNA(_xlfn.XLOOKUP($K20, Power_Patch[Combined Rack Number and Outlet],Power_Patch[Fixture Number]), "") | G20: =_xlfn.IFNA(_xlfn.XLOOKUP($K20, Power_Patch[Combined Rack Number and Outlet],Power_Patch[Location]), "") | H20: =IFERROR(VLOOKUP(E20,ActiveFixtures,2,FALSE),"") | K20: =IF(ISBLANK(C20), "", $D$3&"-"&$C20) -> 2-13
B21: =_xlfn.IFNA(_xlfn.XLOOKUP($K20, Power_Patch[Combined Rack Number and Outlet],Power_Patch[Multi Name]), "") | C21: 14 | D21: =B21&".2" -> .2 | E21: =_xlfn.IFNA(_xlfn.XLOOKUP($K21, Power_Patch[Combined Rack Number and Outlet],Power_Patch[Fixture Type]), "") | F21: =_xlfn.IFNA(_xlfn.XLOOKUP($K21, Power_Patch[Combined Rack Number and Outlet],Power_Patch[Fixture Number]), "") | H21: =IFERROR(VLOOKUP(E21,ActiveFixtures,2,FALSE),"") | K21: =IF(ISBLANK(C21), "", $D$3&"-"&$C21) -> 2-14
C22: 15 | D22: =B21&".3" -> .3 | E22: =_xlfn.IFNA(_xlfn.XLOOKUP($K22, Power_Patch[Combined Rack Number and Outlet],Power_Patch[Fixture Type]), "") | F22: =_xlfn.IFNA(_xlfn.XLOOKUP($K22, Power_Patch[Combined Rack Number and Outlet],Power_Patch[Fixture Number]), "") | H22: =IFERROR(VLOOKUP(E22,ActiveFixtures,2,FALSE),"") | K22: =IF(ISBLANK(C22), "", $D$3&"-"&$C22) -> 2-15
C23: 16 | D23: =B21&".4" -> .4 | E23: =_xlfn.IFNA(_xlfn.XLOOKUP($K23, Power_Patch[Combined Rack Number and Outlet],Power_Patch[Fixture Type]), "") | F23: =_xlfn.IFNA(_xlfn.XLOOKUP($K23, Power_Patch[Combined Rack Number and Outlet],Power_Patch[Fixture Number]), "") | H23: =IFERROR(VLOOKUP(E23,ActiveFixtures,2,FALSE),"") | K23: =IF(ISBLANK(C23), "", $D$3&"-"&$C23) -> 2-16
C24: 17 | D24: =B21&".5" -> .5 | E24: =_xlfn.IFNA(_xlfn.XLOOKUP($K24, Power_Patch[Combined Rack Number and Outlet],Power_Patch[Fixture Type]), "") | F24: =_xlfn.IFNA(_xlfn.XLOOKUP($K24, Power_Patch[Combined Rack Number and Outlet],Power_Patch[Fixture Number]), "") | H24: =IFERROR(VLOOKUP(E24,ActiveFixtures,2,FALSE),"") | K24: =IF(ISBLANK(C24), "", $D$3&"-"&$C24) -> 2-17
C25: 18 | D25: =B21&".6" -> .6 | E25: =_xlfn.IFNA(_xlfn.XLOOKUP($K25, Power_Patch[Combined Rack Number and Outlet],Power_Patch[Fixture Type]), "") | F25: =_xlfn.IFNA(_xlfn.XLOOKUP($K25, Power_Patch[Combined Rack Number and Outlet],Power_Patch[Fixture Number]), "") | H25: =IFERROR(VLOOKUP(E25,ActiveFixtures,2,FALSE),"") | K25: =IF(ISBLANK(C25), "", $D$3&"-"&$C25) -> 2-18
K26: =IF(ISBLANK(C26), "", $D$3&"-"&$C26)
B27: Loom ID | C27: 19 | D27: =B28&".1" -> .1 | E27: =_xlfn.IFNA(_xlfn.XLOOKUP($K27, Power_Patch[Combined Rack Number and Outlet],Power_Patch[Fixture Type]), "") | F27: =_xlfn.IFNA(_xlfn.XLOOKUP($K27, Power_Patch[Combined Rack Number and Outlet],Power_Patch[Fixture Number]), "") | G27: =_xlfn.IFNA(_xlfn.XLOOKUP($K27, Power_Patch[Combined Rack Number and Outlet],Power_Patch[Location]), "") | H27: =IFERROR(VLOOKUP(E27,ActiveFixtures,2,FALSE),"") | K27: =IF(ISBLANK(C27), "", $D$3&"-"&$C27) -> 2-19
B28: =_xlfn.IFNA(_xlfn.XLOOKUP($K27, Power_Patch[Combined Rack Number and Outlet],Power_Patch[Multi Name]), "") | C28: 20 | D28: =B28&".2" -> .2 | E28: =_xlfn.IFNA(_xlfn.XLOOKUP($K28, Power_Patch[Combined Rack Number and Outlet],Power_Patch[Fixture Type]), "") | F28: =_xlfn.IFNA(_xlfn.XLOOKUP($K28, Power_Patch[Combined Rack Number and Outlet],Power_Patch[Fixture Number]), "") | H28: =IFERROR(VLOOKUP(E28,ActiveFixtures,2,FALSE),"") | K28: =IF(ISBLANK(C28), "", $D$3&"-"&$C28) -> 2-20
C29: 21 | D29: =B28&".3" -> .3 | E29: =_xlfn.IFNA(_xlfn.XLOOKUP($K29, Power_Patch[Combined Rack Number and Outlet],Power_Patch[Fixture Type]), "") | F29: =_xlfn.IFNA(_xlfn.XLOOKUP($K29, Power_Patch[Combined Rack Number and Outlet],Power_Patch[Fixture Number]), "") | H29: =IFERROR(VLOOKUP(E29,ActiveFixtures,2,FALSE),"") | K29: =IF(ISBLANK(C29), "", $D$3&"-"&$C29) -> 2-21
C30: 22 | D30: =B28&".4" -> .4 | E30: =_xlfn.IFNA(_xlfn.XLOOKUP($K30, Power_Patch[Combined Rack Number and Outlet],Power_Patch[Fixture Type]), "") | F30: =_xlfn.IFNA(_xlfn.XLOOKUP($K30, Power_Patch[Combined Rack Number and Outlet],Power_Patch[Fixture Number]), "") | H30: =IFERROR(VLOOKUP(E30,ActiveFixtures,2,FALSE),"") | K30: =IF(ISBLANK(C30), "", $D$3&"-"&$C30) -> 2-22
C31: 23 | D31: =B28&".5" -> .5 | E31: =_xlfn.IFNA(_xlfn.XLOOKUP($K31, Power_Patch[Combined Rack Number and Outlet],Power_Patch[Fixture Type]), "") | F31: =_xlfn.IFNA(_xlfn.XLOOKUP($K31, Power_Patch[Combined Rack Number and Outlet],Power_Patch[Fixture Number]), "") | H31: =IFERROR(VLOOKUP(E31,ActiveFixtures,2,FALSE),"") | K31: =IF(ISBLANK(C31), "", $D$3&"-"&$C31) -> 2-23
C32: 24 | D32: =B28&".6" -> .6 | E32: =_xlfn.IFNA(_xlfn.XLOOKUP($K32, Power_Patch[Combined Rack Number and Outlet],Power_Patch[Fixture Type]), "") | F32: =_xlfn.IFNA(_xlfn.XLOOKUP($K32, Power_Patch[Combined Rack Number and Outlet],Power_Patch[Fixture Number]), "") | H32: =IFERROR(VLOOKUP(E32,ActiveFixtures,2,FALSE),"") | K32: =IF(ISBLANK(C32), "", $D$3&"-"&$C32) -> 2-24
K33: =IF(ISBLANK(C33), "", $D$3&"-"&$C33)
B34: Loom ID | C34: 25 | D34: =B35&".1" -> .1 | E34: =_xlfn.IFNA(_xlfn.XLOOKUP($K34, Power_Patch[Combined Rack Number and Outlet],Power_Patch[Fixture Type]), "") | F34: =_xlfn.IFNA(_xlfn.XLOOKUP($K34, Power_Patch[Combined Rack Number and Outlet],Power_Patch[Fixture Number]), "") | G34: =_xlfn.IFNA(_xlfn.XLOOKUP($K34, Power_Patch[Combined Rack Number and Outlet],Power_Patch[Location]), "") | H34: =IFERROR(VLOOKUP(E34,ActiveFixtures,2,FALSE),"") | K34: =IF(ISBLANK(C34), "", $D$3&"-"&$C34) -> 2-25
B35: =_xlfn.IFNA(_xlfn.XLOOKUP($K34, Power_Patch[Combined Rack Number and Outlet],Power_Patch[Multi Name]), "") | C35: 26 | D35: =B35&".2" -> .2 | E35: =_xlfn.IFNA(_xlfn.XLOOKUP($K35, Power_Patch[Combined Rack Number and Outlet],Power_Patch[Fixture Type]), "") | F35: =_xlfn.IFNA(_xlfn.XLOOKUP($K35, Power_Patch[Combined Rack Number and Outlet],Power_Patch[Fixture Number]), "") | H35: =IFERROR(VLOOKUP(E35,ActiveFixtures,2,FALSE),"") | K35: =IF(ISBLANK(C35), "", $D$3&"-"&$C35) -> 2-26
C36: 27 | D36: =B35&".3" -> .3 | E36: =_xlfn.IFNA(_xlfn.XLOOKUP($K36, Power_Patch[Combined Rack Number and Outlet],Power_Patch[Fixture Type]), "") | F36: =_xlfn.IFNA(_xlfn.XLOOKUP($K36, Power_Patch[Combined Rack Number and Outlet],Power_Patch[Fixture Number]), "") | H36: =IFERROR(VLOOKUP(E36,ActiveFixtures,2,FALSE),"") | K36: =IF(ISBLANK(C36), "", $D$3&"-"&$C36) -> 2-27
C37: 28 | D37: =B35&".4" -> .4 | E37: =_xlfn.IFNA(_xlfn.XLOOKUP($K37, Power_Patch[Combined Rack Number and Outlet],Power_Patch[Fixture Type]), "") | F37: =_xlfn.IFNA(_xlfn.XLOOKUP($K37, Power_Patch[Combined Rack Number and Outlet],Power_Patch[Fixture Number]), "") | H37: =IFERROR(VLOOKUP(E37,ActiveFixtures,2,FALSE),"") | K37: =IF(ISBLANK(C37), "", $D$3&"-"&$C37) -> 2-28
C38: 29 | D38: =B35&".5" -> .5 | E38: =_xlfn.IFNA(_xlfn.XLOOKUP($K38, Power_Patch[Combined Rack Number and Outlet],Power_Patch[Fixture Type]), "") | F38: =_xlfn.IFNA(_xlfn.XLOOKUP($K38, Power_Patch[Combined Rack Number and Outlet],Power_Patch[Fixture Number]), "") | H38: =IFERROR(VLOOKUP(E38,ActiveFixtures,2,FALSE),"") | K38: =IF(ISBLANK(C38), "", $D$3&"-"&$C38) -> 2-29
C39: 30 | D39: =B35&".6" -> .6 | E39: =_xlfn.IFNA(_xlfn.XLOOKUP($K39, Power_Patch[Combined Rack Number and Outlet],Power_Patch[Fixture Type]), "") | F39: =_xlfn.IFNA(_xlfn.XLOOKUP($K39, Power_Patch[Combined Rack Number and Outlet],Power_Patch[Fixture Number]), "") | H39: =IFERROR(VLOOKUP(E39,ActiveFixtures,2,FALSE),"") | K39: =IF(ISBLANK(C39), "", $D$3&"-"&$C39) -> 2-30
K40: =IF(ISBLANK(C40), "", $D$3&"-"&$C40)
B41: Loom ID | C41: 31 | D41: =B42&".1" -> .1 | E41: =_xlfn.IFNA(_xlfn.XLOOKUP($K41, Power_Patch[Combined Rack Number and Outlet],Power_Patch[Fixture Type]), "") | F41: =_xlfn.IFNA(_xlfn.XLOOKUP($K41, Power_Patch[Combined Rack Number and Outlet],Power_Patch[Fixture Number]), "") | G41: =_xlfn.IFNA(_xlfn.XLOOKUP($K41, Power_Patch[Combined Rack Number and Outlet],Power_Patch[Location]), "") | H41: =IFERROR(VLOOKUP(E41,ActiveFixtures,2,FALSE),"") | K41: =IF(ISBLANK(C41), "", $D$3&"-"&$C41) -> 2-31
...

Sheet Rack 3
B2: SHOW | D2: =Fixtures!C2 -> Untitled Show
B3: RACK# | D3: 3
B4: NAME / TYPE | D4: =_xlfn.IFNA(_xlfn.XLOOKUP($D$3, Power_Patch[Rack Number],Power_Patch[Rack Name]), "") | F4: =_xlfn.IFNA(_xlfn.XLOOKUP($D$3, Power_Patch[Rack Number],Power_Patch[Rack Type]), "")
C5: CHL | D5: CIRCUT | E5: FIXTURE | F5: FIX. NO. | G5: LOCATION | H5: AMPS | K5: Lookup Value
B6: Loom ID | C6: 1 | D6: =B7&".1" -> .1 | E6: =_xlfn.IFNA(_xlfn.XLOOKUP($K6, Power_Patch[Combined Rack Number and Outlet],Power_Patch[Fixture Type]), "") | F6: =_xlfn.IFNA(_xlfn.XLOOKUP($K6, Power_Patch[Combined Rack Number and Outlet],Power_Patch[Fixture Number]), "") | G6: =_xlfn.IFNA(_xlfn.XLOOKUP($K6, Power_Patch[Combined Rack Number and Outlet],Power_Patch[Location]), "") | H6: =IFERROR(VLOOKUP(E6,ActiveFixtures,2,FALSE),"") | K6: =IF(ISBLANK(C6), "", $D$3&"-"&$C6) -> 3-1
B7: =_xlfn.IFNA(_xlfn.XLOOKUP($K6, Power_Patch[Combined Rack Number and Outlet],Power_Patch[Multi Name]), "") | C7: 2 | D7: =B7&".2" -> .2 | E7: =_xlfn.IFNA(_xlfn.XLOOKUP($K7, Power_Patch[Combined Rack Number and Outlet],Power_Patch[Fixture Type]), "") | F7: =_xlfn.IFNA(_xlfn.XLOOKUP($K7, Power_Patch[Combined Rack Number and Outlet],Power_Patch[Fixture Number]), "") | H7: =IFERROR(VLOOKUP(E7,ActiveFixtures,2,FALSE),"") | K7: =IF(ISBLANK(C7), "", $D$3&"-"&$C7) -> 3-2
C8: 3 | D8: =B7&".3" -> .3 | E8: =_xlfn.IFNA(_xlfn.XLOOKUP($K8, Power_Patch[Combined Rack Number and Outlet],Power_Patch[Fixture Type]), "") | F8: =_xlfn.IFNA(_xlfn.XLOOKUP($K8, Power_Patch[Combined Rack Number and Outlet],Power_Patch[Fixture Number]), "") | H8: =IFERROR(VLOOKUP(E8,ActiveFixtures,2,FALSE),"") | K8: =IF(ISBLANK(C8), "", $D$3&"-"&$C8) -> 3-3
C9: 4 | D9: =B7&".4" -> .4 | E9: =_xlfn.IFNA(_xlfn.XLOOKUP($K9, Power_Patch[Combined Rack Number and Outlet],Power_Patch[Fixture Type]), "") | F9: =_xlfn.IFNA(_xlfn.XLOOKUP($K9, Power_Patch[Combined Rack Number and Outlet],Power_Patch[Fixture Number]), "") | H9: =IFERROR(VLOOKUP(E9,ActiveFixtures,2,FALSE),"") | K9: =IF(ISBLANK(C9), "", $D$3&"-"&$C9) -> 3-4
C10: 5 | D10: =B7&".5" -> .5 | E10: =_xlfn.IFNA(_xlfn.XLOOKUP($K10, Power_Patch[Combined Rack Number and Outlet],Power_Patch[Fixture Type]), "") | F10: =_xlfn.IFNA(_xlfn.XLOOKUP($K10, Power_Patch[Combined Rack Number and Outlet],Power_Patch[Fixture Number]), "") | H10: =IFERROR(VLOOKUP(E10,ActiveFixtures,2,FALSE),"") | K10: =IF(ISBLANK(C10), "", $D$3&"-"&$C10) -> 3-5
C11: 6 | D11: =B7&".6" -> .6 | E11: =_xlfn.IFNA(_xlfn.XLOOKUP($K11, Power_Patch[Combined Rack Number and Outlet],Power_Patch[Fixture Type]), "") | F11: =_xlfn.IFNA(_xlfn.XLOOKUP($K11, Power_Patch[Combined Rack Number and Outlet],Power_Patch[Fixture Number]), "") | H11: =IFERROR(VLOOKUP(E11,ActiveFixtures,2,FALSE),"") | K11: =IF(ISBLANK(C11), "", $D$3&"-"&$C11) -> 3-6
K12: =IF(ISBLANK(C12), "", $D$3&"-"&$C12)
B13: Loom ID | C13: 7 | D13: =B14&".1" -> .1 | E13: =_xlfn.IFNA(_xlfn.XLOOKUP($K13, Power_Patch[Combined Rack Number and Outlet],Power_Patch[Fixture Type]), "") | F13: =_xlfn.IFNA(_xlfn.XLOOKUP($K13, Power_Patch[Combined Rack Number and Outlet],Power_Patch[Fixture Number]), "") | G13: =_xlfn.IFNA(_xlfn.XLOOKUP($K13, Power_Patch[Combined Rack Number and Outlet],Power_Patch[Location]), "") | H13: =IFERROR(VLOOKUP(E13,ActiveFixtures,2,FALSE),"") | K13: =IF(ISBLANK(C13), "", $D$3&"-"&$C13) -> 3-7
B14: =_xlfn.IFNA(_xlfn.XLOOKUP($K13, Power_Patch[Combined Rack Number and Outlet],Power_Patch[Multi Name]), "") | C14: 8 | D14: =B14&".2" -> .2 | E14: =_xlfn.IFNA(_xlfn.XLOOKUP($K14, Power_Patch[Combined Rack Number and Outlet],Power_Patch[Fixture Type]), "") | F14: =_xlfn.IFNA(_xlfn.XLOOKUP($K14, Power_Patch[Combined Rack Number and Outlet],Power_Patch[Fixture Number]), "") | H14: =IFERROR(VLOOKUP(E14,ActiveFixtures,2,FALSE),"") | K14: =IF(ISBLANK(C14), "", $D$3&"-"&$C14) -> 3-8
C15: 9 | D15: =B14&".3" -> .3 | E15: =_xlfn.IFNA(_xlfn.XLOOKUP($K15, Power_Patch[Combined Rack Number and Outlet],Power_Patch[Fixture Type]), "") | F15: =_xlfn.IFNA(_xlfn.XLOOKUP($K15, Power_Patch[Combined Rack Number and Outlet],Power_Patch[Fixture Number]), "") | H15: =IFERROR(VLOOKUP(E15,ActiveFixtures,2,FALSE),"") | K15: =IF(ISBLANK(C15), "", $D$3&"-"&$C15) -> 3-9
C16: 10 | D16: =B14&".4" -> .4 | E16: =_xlfn.IFNA(_xlfn.XLOOKUP($K16, Power_Patch[Combined Rack Number and Outlet],Power_Patch[Fixture Type]), "") | F16: =_xlfn.IFNA(_xlfn.XLOOKUP($K16, Power_Patch[Combined Rack Number and Outlet],Power_Patch[Fixture Number]), "") | H16: =IFERROR(VLOOKUP(E16,ActiveFixtures,2,FALSE),"") | K16: =IF(ISBLANK(C16), "", $D$3&"-"&$C16) -> 3-10
C17: 11 | D17: =B14&".5" -> .5 | E17: =_xlfn.IFNA(_xlfn.XLOOKUP($K17, Power_Patch[Combined Rack Number and Outlet],Power_Patch[Fixture Type]), "") | F17: =_xlfn.IFNA(_xlfn.XLOOKUP($K17, Power_Patch[Combined Rack Number and Outlet],Power_Patch[Fixture Number]), "") | H17: =IFERROR(VLOOKUP(E17,ActiveFixtures,2,FALSE),"") | K17: =IF(ISBLANK(C17), "", $D$3&"-"&$C17) -> 3-11
C18: 12 | D18: =B14&".6" -> .6 | E18: =_xlfn.IFNA(_xlfn.XLOOKUP($K18, Power_Patch[Combined Rack Number and Outlet],Power_Patch[Fixture Type]), "") | F18: =_xlfn.IFNA(_xlfn.XLOOKUP($K18, Power_Patch[Combined Rack Number and Outlet],Power_Patch[Fixture Number]), "") | H18: =IFERROR(VLOOKUP(E18,ActiveFixtures,2,FALSE),"") | K18: =IF(ISBLANK(C18), "", $D$3&"-"&$C18) -> 3-12
K19: =IF(ISBLANK(C19), "", $D$3&"-"&$C19)
B20: Loom ID | C20: 13 | D20: =B21&".1" -> .1 | E20: =_xlfn.IFNA(_xlfn.XLOOKUP($K20, Power_Patch[Combined Rack Number and Outlet],Power_Patch[Fixture Type]), "") | F20: =_xlfn.IFNA(_xlfn.XLOOKUP($K20, Power_Patch[Combined Rack Number and Outlet],Power_Patch[Fixture Number]), "") | G20: =_xlfn.IFNA(_xlfn.XLOOKUP($K20, Power_Patch[Combined Rack Number and Outlet],Power_Patch[Location]), "") | H20: =IFERROR(VLOOKUP(E20,ActiveFixtures,2,FALSE),"") | K20: =IF(ISBLANK(C20), "", $D$3&"-"&$C20) -> 3-13
B21: =_xlfn.IFNA(_xlfn.XLOOKUP($K20, Power_Patch[Combined Rack Number and Outlet],Power_Patch[Multi Name]), "") | C21: 14 | D21: =B21&".2" -> .2 | E21: =_xlfn.IFNA(_xlfn.XLOOKUP($K21, Power_Patch[Combined Rack Number and Outlet],Power_Patch[Fixture Type]), "") | F21: =_xlfn.IFNA(_xlfn.XLOOKUP($K21, Power_Patch[Combined Rack Number and Outlet],Power_Patch[Fixture Number]), "") | H21: =IFERROR(VLOOKUP(E21,ActiveFixtures,2,FALSE),"") | K21: =IF(ISBLANK(C21), "", $D$3&"-"&$C21) -> 3-14
C22: 15 | D22: =B21&".3" -> .3 | E22: =_xlfn.IFNA(_xlfn.XLOOKUP($K22, Power_Patch[Combined Rack Number and Outlet],Power_Patch[Fixture Type]), "") | F22: =_xlfn.IFNA(_xlfn.XLOOKUP($K22, Power_Patch[Combined Rack Number and Outlet],Power_Patch[Fixture Number]), "") | H22: =IFERROR(VLOOKUP(E22,ActiveFixtures,2,FALSE),"") | K22: =IF(ISBLANK(C22), "", $D$3&"-"&$C22) -> 3-15
C23: 16 | D23: =B21&".4" -> .4 | E23: =_xlfn.IFNA(_xlfn.XLOOKUP($K23, Power_Patch[Combined Rack Number and Outlet],Power_Patch[Fixture Type]), "") | F23: =_xlfn.IFNA(_xlfn.XLOOKUP($K23, Power_Patch[Combined Rack Number and Outlet],Power_Patch[Fixture Number]), "") | H23: =IFERROR(VLOOKUP(E23,ActiveFixtures,2,FALSE),"") | K23: =IF(ISBLANK(C23), "", $D$3&"-"&$C23) -> 3-16
C24: 17 | D24: =B21&".5" -> .5 | E24: =_xlfn.IFNA(_xlfn.XLOOKUP($K24, Power_Patch[Combined Rack Number and Outlet],Power_Patch[Fixture Type]), "") | F24: =_xlfn.IFNA(_xlfn.XLOOKUP($K24, Power_Patch[Combined Rack Number and Outlet],Power_Patch[Fixture Number]), "") | H24: =IFERROR(VLOOKUP(E24,ActiveFixtures,2,FALSE),"") | K24: =IF(ISBLANK(C24), "", $D$3&"-"&$C24) -> 3-17
C25: 18 | D25: =B21&".6" -> .6 | E25: =_xlfn.IFNA(_xlfn.XLOOKUP($K25, Power_Patch[Combined Rack Number and Outlet],Power_Patch[Fixture Type]), "") | F25: =_xlfn.IFNA(_xlfn.XLOOKUP($K25, Power_Patch[Combined Rack Number and Outlet],Power_Patch[Fixture Number]), "") | H25: =IFERROR(VLOOKUP(E25,ActiveFixtures,2,FALSE),"") | K25: =IF(ISBLANK(C25), "", $D$3&"-"&$C25) -> 3-18
K26: =IF(ISBLANK(C26), "", $D$3&"-"&$C26)
B27: Loom ID | C27: 19 | D27: =B28&".1" -> .1 | E27: =_xlfn.IFNA(_xlfn.XLOOKUP($K27, Power_Patch[Combined Rack Number and Outlet],Power_Patch[Fixture Type]), "") | F27: =_xlfn.IFNA(_xlfn.XLOOKUP($K27, Power_Patch[Combined Rack Number and Outlet],Power_Patch[Fixture Number]), "") | G27: =_xlfn.IFNA(_xlfn.XLOOKUP($K27, Power_Patch[Combined Rack Number and Outlet],Power_Patch[Location]), "") | H27: =IFERROR(VLOOKUP(E27,ActiveFixtures,2,FALSE),"") | K27: =IF(ISBLANK(C27), "", $D$3&"-"&$C27) -> 3-19
B28: =_xlfn.IFNA(_xlfn.XLOOKUP($K27, Power_Patch[Combined Rack Number and Outlet],Power_Patch[Multi Name]), "") | C28: 20 | D28: =B28&".2" -> .2 | E28: =_xlfn.IFNA(_xlfn.XLOOKUP($K28, Power_Patch[Combined Rack Number and Outlet],Power_Patch[Fixture Type]), "") | F28: =_xlfn.IFNA(_xlfn.XLOOKUP($K28, Power_Patch[Combined Rack Number and Outlet],Power_Patch[Fixture Number]), "") | H28: =IFERROR(VLOOKUP(E28,ActiveFixtures,2,FALSE),"") | K28: =IF(ISBLANK(C28), "", $D$3&"-"&$C28) -> 3-20
C29: 21 | D29: =B28&".3" -> .3 | E29: =_xlfn.IFNA(_xlfn.XLOOKUP($K29, Power_Patch[Combined Rack Number and Outlet],Power_Patch[Fixture Type]), "") | F29: =_xlfn.IFNA(_xlfn.XLOOKUP($K29, Power_Patch[Combined Rack Number and Outlet],Power_Patch[Fixture Number]), "") | H29: =IFERROR(VLOOKUP(E29,ActiveFixtures,2,FALSE),"") | K29: =IF(ISBLANK(C29), "", $D$3&"-"&$C29) -> 3-21
C30: 22 | D30: =B28&".4" -> .4 | E30: =_xlfn.IFNA(_xlfn.XLOOKUP($K30, Power_Patch[Combined Rack Number and Outlet],Power_Patch[Fixture Type]), "") | F30: =_xlfn.IFNA(_xlfn.XLOOKUP($K30, Power_Patch[Combined Rack Number and Outlet],Power_Patch[Fixture Number]), "") | H30: =IFERROR(VLOOKUP(E30,ActiveFixtures,2,FALSE),"") | K30: =IF(ISBLANK(C30), "", $D$3&"-"&$C30) -> 3-22
C31: 23 | D31: =B28&".5" -> .5 | E31: =_xlfn.IFNA(_xlfn.XLOOKUP($K31, Power_Patch[Combined Rack Number and Outlet],Power_Patch[Fixture Type]), "") | F31: =_xlfn.IFNA(_xlfn.XLOOKUP($K31, Power_Patch[Combined Rack Number and Outlet],Power_Patch[Fixture Number]), "") | H31: =IFERROR(VLOOKUP(E31,ActiveFixtures,2,FALSE),"") | K31: =IF(ISBLANK(C31), "", $D$3&"-"&$C31) -> 3-23
C32: 24 | D32: =B28&".6" -> .6 | E32: =_xlfn.IFNA(_xlfn.XLOOKUP($K32, Power_Patch[Combined Rack Number and Outlet],Power_Patch[Fixture Type]), "") | F32: =_xlfn.IFNA(_xlfn.XLOOKUP($K32, Power_Patch[Combined Rack Number and Outlet],Power_Patch[Fixture Number]), "") | H32: =IFERROR(VLOOKUP(E32,ActiveFixtures,2,FALSE),"") | K32: =IF(ISBLANK(C32), "", $D$3&"-"&$C32) -> 3-24
K33: =IF(ISBLANK(C33), "", $D$3&"-"&$C33)
B34: Loom ID | C34: 25 | D34: =B35&".1" -> .1 | E34: =_xlfn.IFNA(_xlfn.XLOOKUP($K34, Power_Patch[Combined Rack Number and Outlet],Power_Patch[Fixture Type]), "") | F34: =_xlfn.IFNA(_xlfn.XLOOKUP($K34, Power_Patch[Combined Rack Number and Outlet],Power_Patch[Fixture Number]), "") | G34: =_xlfn.IFNA(_xlfn.XLOOKUP($K34, Power_Patch[Combined Rack Number and Outlet],Power_Patch[Location]), "") | H34: =IFERROR(VLOOKUP(E34,ActiveFixtures,2,FALSE),"") | K34: =IF(ISBLANK(C34), "", $D$3&"-"&$C34) -> 3-25
B35: =_xlfn.IFNA(_xlfn.XLOOKUP($K34, Power_Patch[Combined Rack Number and Outlet],Power_Patch[Multi Name]), "") | C35: 26 | D35: =B35&".2" -> .2 | E35: =_xlfn.IFNA(_xlfn.XLOOKUP($K35, Power_Patch[Combined Rack Number and Outlet],Power_Patch[Fixture Type]), "") | F35: =_xlfn.IFNA(_xlfn.XLOOKUP($K35, Power_Patch[Combined Rack Number and Outlet],Power_Patch[Fixture Number]), "") | H35: =IFERROR(VLOOKUP(E35,ActiveFixtures,2,FALSE),"") | K35: =IF(ISBLANK(C35), "", $D$3&"-"&$C35) -> 3-26
C36: 27 | D36: =B35&".3" -> .3 | E36: =_xlfn.IFNA(_xlfn.XLOOKUP($K36, Power_Patch[Combined Rack Number and Outlet],Power_Patch[Fixture Type]), "") | F36: =_xlfn.IFNA(_xlfn.XLOOKUP($K36, Power_Patch[Combined Rack Number and Outlet],Power_Patch[Fixture Number]), "") | H36: =IFERROR(VLOOKUP(E36,ActiveFixtures,2,FALSE),"") | K36: =IF(ISBLANK(C36), "", $D$3&"-"&$C36) -> 3-27
C37: 28 | D37: =B35&".4" -> .4 | E37: =_xlfn.IFNA(_xlfn.XLOOKUP($K37, Power_Patch[Combined Rack Number and Outlet],Power_Patch[Fixture Type]), "") | F37: =_xlfn.IFNA(_xlfn.XLOOKUP($K37, Power_Patch[Combined Rack Number and Outlet],Power_Patch[Fixture Number]), "") | H37: =IFERROR(VLOOKUP(E37,ActiveFixtures,2,FALSE),"") | K37: =IF(ISBLANK(C37), "", $D$3&"-"&$C37) -> 3-28
C38: 29 | D38: =B35&".5" -> .5 | E38: =_xlfn.IFNA(_xlfn.XLOOKUP($K38, Power_Patch[Combined Rack Number and Outlet],Power_Patch[Fixture Type]), "") | F38: =_xlfn.IFNA(_xlfn.XLOOKUP($K38, Power_Patch[Combined Rack Number and Outlet],Power_Patch[Fixture Number]), "") | H38: =IFERROR(VLOOKUP(E38,ActiveFixtures,2,FALSE),"") | K38: =IF(ISBLANK(C38), "", $D$3&"-"&$C38) -> 3-29
C39: 30 | D39: =B35&".6" -> .6 | E39: =_xlfn.IFNA(_xlfn.XLOOKUP($K39, Power_Patch[Combined Rack Number and Outlet],Power_Patch[Fixture Type]), "") | F39: =_xlfn.IFNA(_xlfn.XLOOKUP($K39, Power_Patch[Combined Rack Number and Outlet],Power_Patch[Fixture Number]), "") | H39: =IFERROR(VLOOKUP(E39,ActiveFixtures,2,FALSE),"") | K39: =IF(ISBLANK(C39), "", $D$3&"-"&$C39) -> 3-30
K40: =IF(ISBLANK(C40), "", $D$3&"-"&$C40)
B41: Loom ID | C41: 31 | D41: =B42&".1" -> .1 | E41: =_xlfn.IFNA(_xlfn.XLOOKUP($K41, Power_Patch[Combined Rack Number and Outlet],Power_Patch[Fixture Type]), "") | F41: =_xlfn.IFNA(_xlfn.XLOOKUP($K41, Power_Patch[Combined Rack Number and Outlet],Power_Patch[Fixture Number]), "") | G41: =_xlfn.IFNA(_xlfn.XLOOKUP($K41, Power_Patch[Combined Rack Number and Outlet],Power_Patch[Location]), "") | H41: =IFERROR(VLOOKUP(E41,ActiveFixtures,2,FALSE),"") | K41: =IF(ISBLANK(C41), "", $D$3&"-"&$C41) -> 3-31
...

Sheet Rack 4
B2: SHOW | D2: =Fixtures!C2 -> Untitled Show
B3: RACK# | D3: 4
B4: NAME / TYPE | D4: =_xlfn.IFNA(_xlfn.XLOOKUP($D$3, Power_Patch[Rack Number],Power_Patch[Rack Name]), "") | F4: =_xlfn.IFNA(_xlfn.XLOOKUP($D$3, Power_Patch[Rack Number],Power_Patch[Rack Type]), "")
C5: CHL | D5: CIRCUT | E5: FIXTURE | F5: FIX. NO. | G5: LOCATION | H5: AMPS | K5: Lookup Value
B6: Loom ID | C6: 1 | D6: =B7&".1" -> .1 | E6: =_xlfn.IFNA(_xlfn.XLOOKUP($K6, Power_Patch[Combined Rack Number and Outlet],Power_Patch[Fixture Type]), "") | F6: =_xlfn.IFNA(_xlfn.XLOOKUP($K6, Power_Patch[Combined Rack Number and Outlet],Power_Patch[Fixture Number]), "") | G6: =_xlfn.IFNA(_xlfn.XLOOKUP($K6, Power_Patch[Combined Rack Number and Outlet],Power_Patch[Location]), "") | H6: =IFERROR(VLOOKUP(E6,ActiveFixtures,2,FALSE),"") | K6: =IF(ISBLANK(C6), "", $D$3&"-"&$C6) -> 4-1
B7: =_xlfn.IFNA(_xlfn.XLOOKUP($K6, Power_Patch[Combined Rack Number and Outlet],Power_Patch[Multi Name]), "") | C7: 2 | D7: =B7&".2" -> .2 | E7: =_xlfn.IFNA(_xlfn.XLOOKUP($K7, Power_Patch[Combined Rack Number and Outlet],Power_Patch[Fixture Type]), "") | F7: =_xlfn.IFNA(_xlfn.XLOOKUP($K7, Power_Patch[Combined Rack Number and Outlet],Power_Patch[Fixture Number]), "") | H7: =IFERROR(VLOOKUP(E7,ActiveFixtures,2,FALSE),"") | K7: =IF(ISBLANK(C7), "", $D$3&"-"&$C7) -> 4-2
C8: 3 | D8: =B7&".3" -> .3 | E8: =_xlfn.IFNA(_xlfn.XLOOKUP($K8, Power_Patch[Combined Rack Number and Outlet],Power_Patch[Fixture Type]), "") | F8: =_xlfn.IFNA(_xlfn.XLOOKUP($K8, Power_Patch[Combined Rack Number and Outlet],Power_Patch[Fixture Number]), "") | H8: =IFERROR(VLOOKUP(E8,ActiveFixtures,2,FALSE),"") | K8: =IF(ISBLANK(C8), "", $D$3&"-"&$C8) -> 4-3
C9: 4 | D9: =B7&".4" -> .4 | E9: =_xlfn.IFNA(_xlfn.XLOOKUP($K9, Power_Patch[Combined Rack Number and Outlet],Power_Patch[Fixture Type]), "") | F9: =_xlfn.IFNA(_xlfn.XLOOKUP($K9, Power_Patch[Combined Rack Number and Outlet],Power_Patch[Fixture Number]), "") | H9: =IFERROR(VLOOKUP(E9,ActiveFixtures,2,FALSE),"") | K9: =IF(ISBLANK(C9), "", $D$3&"-"&$C9) -> 4-4
C10: 5 | D10: =B7&".5" -> .5 | E10: =_xlfn.IFNA(_xlfn.XLOOKUP($K10, Power_Patch[Combined Rack Number and Outlet],Power_Patch[Fixture Type]), "") | F10: =_xlfn.IFNA(_xlfn.XLOOKUP($K10, Power_Patch[Combined Rack Number and Outlet],Power_Patch[Fixture Number]), "") | H10: =IFERROR(VLOOKUP(E10,ActiveFixtures,2,FALSE),"") | K10: =IF(ISBLANK(C10), "", $D$3&"-"&$C10) -> 4-5
C11: 6 | D11: =B7&".6" -> .6 | E11: =_xlfn.IFNA(_xlfn.XLOOKUP($K11, Power_Patch[Combined Rack Number and Outlet],Power_Patch[Fixture Type]), "") | F11: =_xlfn.IFNA(_xlfn.XLOOKUP($K11, Power_Patch[Combined Rack Number and Outlet],Power_Patch[Fixture Number]), "") | H11: =IFERROR(VLOOKUP(E11,ActiveFixtures,2,FALSE),"") | K11: =IF(ISBLANK(C11), "", $D$3&"-"&$C11) -> 4-6
K12: =IF(ISBLANK(C12), "", $D$3&"-"&$C12)
B13: Loom ID | C13: 7 | D13: =B14&".1" -> .1 | E13: =_xlfn.IFNA(_xlfn.XLOOKUP($K13, Power_Patch[Combined Rack Number and Outlet],Power_Patch[Fixture Type]), "") | F13: =_xlfn.IFNA(_xlfn.XLOOKUP($K13, Power_Patch[Combined Rack Number and Outlet],Power_Patch[Fixture Number]), "") | G13: =_xlfn.IFNA(_xlfn.XLOOKUP($K13, Power_Patch[Combined Rack Number and Outlet],Power_Patch[Location]), "") | H13: =IFERROR(VLOOKUP(E13,ActiveFixtures,2,FALSE),"") | K13: =IF(ISBLANK(C13), "", $D$3&"-"&$C13) -> 4-7
B14: =_xlfn.IFNA(_xlfn.XLOOKUP($K13, Power_Patch[Combined Rack Number and Outlet],Power_Patch[Multi Name]), "") | C14: 8 | D14: =B14&".2" -> .2 | E14: =_xlfn.IFNA(_xlfn.XLOOKUP($K14, Power_Patch[Combined Rack Number and Outlet],Power_Patch[Fixture Type]), "") | F14: =_xlfn.IFNA(_xlfn.XLOOKUP($K14, Power_Patch[Combined Rack Number and Outlet],Power_Patch[Fixture Number]), "") | H14: =IFERROR(VLOOKUP(E14,ActiveFixtures,2,FALSE),"") | K14: =IF(ISBLANK(C14), "", $D$3&"-"&$C14) -> 4-8
C15: 9 | D15: =B14&".3" -> .3 | E15: =_xlfn.IFNA(_xlfn.XLOOKUP($K15, Power_Patch[Combined Rack Number and Outlet],Power_Patch[Fixture Type]), "") | F15: =_xlfn.IFNA(_xlfn.XLOOKUP($K15, Power_Patch[Combined Rack Number and Outlet],Power_Patch[Fixture Number]), "") | H15: =IFERROR(VLOOKUP(E15,ActiveFixtures,2,FALSE),"") | K15: =IF(ISBLANK(C15), "", $D$3&"-"&$C15) -> 4-9
C16: 10 | D16: =B14&".4" -> .4 | E16: =_xlfn.IFNA(_xlfn.XLOOKUP($K16, Power_Patch[Combined Rack Number and Outlet],Power_Patch[Fixture Type]), "") | F16: =_xlfn.IFNA(_xlfn.XLOOKUP($K16, Power_Patch[Combined Rack Number and Outlet],Power_Patch[Fixture Number]), "") | H16: =IFERROR(VLOOKUP(E16,ActiveFixtures,2,FALSE),"") | K16: =IF(ISBLANK(C16), "", $D$3&"-"&$C16) -> 4-10
C17: 11 | D17: =B14&".5" -> .5 | E17: =_xlfn.IFNA(_xlfn.XLOOKUP($K17, Power_Patch[Combined Rack Number and Outlet],Power_Patch[Fixture Type]), "") | F17: =_xlfn.IFNA(_xlfn.XLOOKUP($K17, Power_Patch[Combined Rack Number and Outlet],Power_Patch[Fixture Number]), "") | H17: =IFERROR(VLOOKUP(E17,ActiveFixtures,2,FALSE),"") | K17: =IF(ISBLANK(C17), "", $D$3&"-"&$C17) -> 4-11
C18: 12 | D18: =B14&".6" -> .6 | E18: =_xlfn.IFNA(_xlfn.XLOOKUP($K18, Power_Patch[Combined Rack Number and Outlet],Power_Patch[Fixture Type]), "") | F18: =_xlfn.IFNA(_xlfn.XLOOKUP($K18, Power_Patch[Combined Rack Number and Outlet],Power_Patch[Fixture Number]), "") | H18: =IFERROR(VLOOKUP(E18,ActiveFixtures,2,FALSE),"") | K18: =IF(ISBLANK(C18), "", $D$3&"-"&$C18) -> 4-12
K19: =IF(ISBLANK(C19), "", $D$3&"-"&$C19)
B20: Loom ID | C20: 13 | D20: =B21&".1" -> .1 | E20: =_xlfn.IFNA(_xlfn.XLOOKUP($K20, Power_Patch[Combined Rack Number and Outlet],Power_Patch[Fixture Type]), "") | F20: =_xlfn.IFNA(_xlfn.XLOOKUP($K20, Power_Patch[Combined Rack Number and Outlet],Power_Patch[Fixture Number]), "") | G20: =_xlfn.IFNA(_xlfn.XLOOKUP($K20, Power_Patch[Combined Rack Number and Outlet],Power_Patch[Location]), "") | H20: =IFERROR(VLOOKUP(E20,ActiveFixtures,2,FALSE),"") | K20: =IF(ISBLANK(C20), "", $D$3&"-"&$C20) -> 4-13
B21: =_xlfn.IFNA(_xlfn.XLOOKUP($K20, Power_Patch[Combined Rack Number and Outlet],Power_Patch[Multi Name]), "") | C21: 14 | D21: =B21&".2" -> .2 | E21: =_xlfn.IFNA(_xlfn.XLOOKUP($K21, Power_Patch[Combined Rack Number and Outlet],Power_Patch[Fixture Type]), "") | F21: =_xlfn.IFNA(_xlfn.XLOOKUP($K21, Power_Patch[Combined Rack Number and Outlet],Power_Patch[Fixture Number]), "") | H21: =IFERROR(VLOOKUP(E21,ActiveFixtures,2,FALSE),"") | K21: =IF(ISBLANK(C21), "", $D$3&"-"&$C21) -> 4-14
C22: 15 | D22: =B21&".3" -> .3 | E22: =_xlfn.IFNA(_xlfn.XLOOKUP($K22, Power_Patch[Combined Rack Number and Outlet],Power_Patch[Fixture Type]), "") | F22: =_xlfn.IFNA(_xlfn.XLOOKUP($K22, Power_Patch[Combined Rack Number and Outlet],Power_Patch[Fixture Number]), "") | H22: =IFERROR(VLOOKUP(E22,ActiveFixtures,2,FALSE),"") | K22: =IF(ISBLANK(C22), "", $D$3&"-"&$C22) -> 4-15
C23: 16 | D23: =B21&".4" -> .4 | E23: =_xlfn.IFNA(_xlfn.XLOOKUP($K23, Power_Patch[Combined Rack Number and Outlet],Power_Patch[Fixture Type]), "") | F23: =_xlfn.IFNA(_xlfn.XLOOKUP($K23, Power_Patch[Combined Rack Number and Outlet],Power_Patch[Fixture Number]), "") | H23: =IFERROR(VLOOKUP(E23,ActiveFixtures,2,FALSE),"") | K23: =IF(ISBLANK(C23), "", $D$3&"-"&$C23) -> 4-16
C24: 17 | D24: =B21&".5" -> .5 | E24: =_xlfn.IFNA(_xlfn.XLOOKUP($K24, Power_Patch[Combined Rack Number and Outlet],Power_Patch[Fixture Type]), "") | F24: =_xlfn.IFNA(_xlfn.XLOOKUP($K24, Power_Patch[Combined Rack Number and Outlet],Power_Patch[Fixture Number]), "") | H24: =IFERROR(VLOOKUP(E24,ActiveFixtures,2,FALSE),"") | K24: =IF(ISBLANK(C24), "", $D$3&"-"&$C24) -> 4-17
C25: 18 | D25: =B21&".6" -> .6 | E25: =_xlfn.IFNA(_xlfn.XLOOKUP($K25, Power_Patch[Combined Rack Number and Outlet],Power_Patch[Fixture Type]), "") | F25: =_xlfn.IFNA(_xlfn.XLOOKUP($K25, Power_Patch[Combined Rack Number and Outlet],Power_Patch[Fixture Number]), "") | H25: =IFERROR(VLOOKUP(E25,ActiveFixtures,2,FALSE),"") | K25: =IF(ISBLANK(C25), "", $D$3&"-"&$C25) -> 4-18
K26: =IF(ISBLANK(C26), "", $D$3&"-"&$C26)
B27: Loom ID | C27: 19 | D27: =B28&".1" -> .1 | E27: =_xlfn.IFNA(_xlfn.XLOOKUP($K27, Power_Patch[Combined Rack Number and Outlet],Power_Patch[Fixture Type]), "") | F27: =_xlfn.IFNA(_xlfn.XLOOKUP($K27, Power_Patch[Combined Rack Number and Outlet],Power_Patch[Fixture Number]), "") | G27: =_xlfn.IFNA(_xlfn.XLOOKUP($K27, Power_Patch[Combined Rack Number and Outlet],Power_Patch[Location]), "") | H27: =IFERROR(VLOOKUP(E27,ActiveFixtures,2,FALSE),"") | K27: =IF(ISBLANK(C27), "", $D$3&"-"&$C27) -> 4-19
B28: =_xlfn.IFNA(_xlfn.XLOOKUP($K27, Power_Patch[Combined Rack Number and Outlet],Power_Patch[Multi Name]), "") | C28: 20 | D28: =B28&".2" -> .2 | E28: =_xlfn.IFNA(_xlfn.XLOOKUP($K28, Power_Patch[Combined Rack Number and Outlet],Power_Patch[Fixture Type]), "") | F28: =_xlfn.IFNA(_xlfn.XLOOKUP($K28, Power_Patch[Combined Rack Number and Outlet],Power_Patch[Fixture Number]), "") | H28: =IFERROR(VLOOKUP(E28,ActiveFixtures,2,FALSE),"") | K28: =IF(ISBLANK(C28), "", $D$3&"-"&$C28) -> 4-20
C29: 21 | D29: =B28&".3" -> .3 | E29: =_xlfn.IFNA(_xlfn.XLOOKUP($K29, Power_Patch[Combined Rack Number and Outlet],Power_Patch[Fixture Type]), "") | F29: =_xlfn.IFNA(_xlfn.XLOOKUP($K29, Power_Patch[Combined Rack Number and Outlet],Power_Patch[Fixture Number]), "") | H29: =IFERROR(VLOOKUP(E29,ActiveFixtures,2,FALSE),"") | K29: =IF(ISBLANK(C29), "", $D$3&"-"&$C29) -> 4-21
C30: 22 | D30: =B28&".4" -> .4 | E30: =_xlfn.IFNA(_xlfn.XLOOKUP($K30, Power_Patch[Combined Rack Number and Outlet],Power_Patch[Fixture Type]), "") | F30: =_xlfn.IFNA(_xlfn.XLOOKUP($K30, Power_Patch[Combined Rack Number and Outlet],Power_Patch[Fixture Number]), "") | H30: =IFERROR(VLOOKUP(E30,ActiveFixtures,2,FALSE),"") | K30: =IF(ISBLANK(C30), "", $D$3&"-"&$C30) -> 4-22
C31: 23 | D31: =B28&".5" -> .5 | E31: =_xlfn.IFNA(_xlfn.XLOOKUP($K31, Power_Patch[Combined Rack Number and Outlet],Power_Patch[Fixture Type]), "") | F31: =_xlfn.IFNA(_xlfn.XLOOKUP($K31, Power_Patch[Combined Rack Number and Outlet],Power_Patch[Fixture Number]), "") | H31: =IFERROR(VLOOKUP(E31,ActiveFixtures,2,FALSE),"") | K31: =IF(ISBLANK(C31), "", $D$3&"-"&$C31) -> 4-23
C32: 24 | D32: =B28&".6" -> .6 | E32: =_xlfn.IFNA(_xlfn.XLOOKUP($K32, Power_Patch[Combined Rack Number and Outlet],Power_Patch[Fixture Type]), "") | F32: =_xlfn.IFNA(_xlfn.XLOOKUP($K32, Power_Patch[Combined Rack Number and Outlet],Power_Patch[Fixture Number]), "") | H32: =IFERROR(VLOOKUP(E32,ActiveFixtures,2,FALSE),"") | K32: =IF(ISBLANK(C32), "", $D$3&"-"&$C32) -> 4-24
K33: =IF(ISBLANK(C33), "", $D$3&"-"&$C33)
B34: Loom ID | C34: 25 | D34: =B35&".1" -> .1 | E34: =_xlfn.IFNA(_xlfn.XLOOKUP($K34, Power_Patch[Combined Rack Number and Outlet],Power_Patch[Fixture Type]), "") | F34: =_xlfn.IFNA(_xlfn.XLOOKUP($K34, Power_Patch[Combined Rack Number and Outlet],Power_Patch[Fixture Number]), "") | G34: =_xlfn.IFNA(_xlfn.XLOOKUP($K34, Power_Patch[Combined Rack Number and Outlet],Power_Patch[Location]), "") | H34: =IFERROR(VLOOKUP(E34,ActiveFixtures,2,FALSE),"") | K34: =IF(ISBLANK(C34), "", $D$3&"-"&$C34) -> 4-25
B35: =_xlfn.IFNA(_xlfn.XLOOKUP($K34, Power_Patch[Combined Rack Number and Outlet],Power_Patch[Multi Name]), "") | C35: 26 | D35: =B35&".2" -> .2 | E35: =_xlfn.IFNA(_xlfn.XLOOKUP($K35, Power_Patch[Combined Rack Number and Outlet],Power_Patch[Fixture Type]), "") | F35: =_xlfn.IFNA(_xlfn.XLOOKUP($K35, Power_Patch[Combined Rack Number and Outlet],Power_Patch[Fixture Number]), "") | H35: =IFERROR(VLOOKUP(E35,ActiveFixtures,2,FALSE),"") | K35: =IF(ISBLANK(C35), "", $D$3&"-"&$C35) -> 4-26
